Workbook

Sheet WBS
A2: Chromebook セキュリティ評価 WBS（改訂版 v3）
A3: 暫定計画：2026/10/07～11/10。実機・仕様確認・既存証跡を分け、追加試験は必要時のみ実施する。 T列のv3区分は前版（v2）からの変更を示す。
J4: 工数合計 | L4: =SUM(L6:L59) -> 22.4 | R4: 条件付き追加 合計 | S4: =SUM(S6:S59) -> 1.5
A5: WBS ID | B5: 大項目 | C5: 中項目 | D5: 小項目 | E5: 実施内容・確認手順 | F5: 完了条件 | G5: 証跡・成果物 | H5: 評価方法 | I5: 主対応枝番号（F列） | J5: 開始予定 | K5: 終了予定 | L5: 基本工数（人日） | M5: 前提・依存WBS | N5: 主担当（案） | O5: 協力先（案） | P5: 状態 | Q5: 参考資料ID | R5: 実施区分 | S5: 追加工数（人日） | T5: v3区分 | U5: v3変更要約
A6: 1.01 | B6: 1. 評価準備・環境構築 | C6: 評価範囲 | D6: 利用構成・責任分界の確定 | E6: 利用業務、Drive／M365／VDI、社内サーバー接続、扱うデータ、管理対象端末を整理する。ChromeOS端末と接続先の評価責任を分ける。初日に評価責任者へ、O～Xの評価対象範囲（Chromebook導入範囲か全社か）と2024年説明資料の入手を依頼する。 | F6: 評価境界・対象サービス・責任者を関係者が合意している。評価対象範囲と説明資料の確認依頼を発出済み。 | G6: 構成図・データフロー・責任分界表 | H6: 設計確認 | I6: 横断・補足（個別対応は対応表） | J6: 46302 | K6: 46302 | L6: 0.5 | M6: なし | N6: SE（氏名未定） | O6: 業務担当・セキュリティ担当 | P6: 未着手 | Q6: I01,G01 | R6: 計画・評価・運用 | T6: 変更 | U6: 初日に評価対象範囲・2024年説明資料の確認依頼を追加（工数据置）
A7: 1.02 | B7: 1. 評価準備・環境構築 | C7: 評価範囲 | D7: 231項目の適用性・担当割当 | E7: 評価項目対応表を全行確認し、対象／対象外／確認中、実機試験／仕様確認／運用証跡を決める。Windows、AD、DC、IaC、OTは接続先も確認する。原票の入力ルール（N列の参照エラー、DC＝ドメインコントローラー、n/aの意味、O列の全行入力、旧期限）を確認して確定する。担当部署・回答責任者・回答者（原票V～X）を割り当て、証跡依頼パッケージ（4.04a～d、5.01、5.07a、5.08向け。回答期限付き）を10/9までに送付する。 | F7: 231項目に担当（V～X）と評価方法があり、対象外理由と未確定事項が明示されている。入力ルールが確定し、証跡依頼が回答期限付きで送付されている。 | G7: 適用性一覧・証跡依頼一覧・入力ルール確認記録 | H7: 資料確認 | I7: 36, 37, 4, 5, 6, 7 | J7: 46302 | K7: 46304 | L7: 1.25 | M7: 1.01 | N7: SE（氏名未定） | O7: 各システム管理者・セキュリティ担当 | P7: 未着手 | Q7: I01,I02 | R7: 計画・評価・運用 | T7: 変更 | U7: 旧6.02の入力ルール確認を前倒しで統合（+0.25）。証跡依頼を10/9までに送付
A8: 1.03 | B8: 1. 評価準備・環境構築 | C8: 評価基準 | D8: 合格条件・成熟度基準の合意 | E8: 社内の2024年説明資料を入手し成熟度基準を確認する。O～Xの評価対象範囲（Chromebook導入範囲／全社）と、複数システム時の案分方法（原票D36）、会社名コードを評価責任者と確認する。ロック時間、更新期限、ログ期間、RPO／RTO、導入不可条件を決める。 | F8: PoC合否と運用成熟度を区別し、評価対象範囲・案分方針・判定基準が承認されている。 | G8: 評価基準・合格条件一覧 | H8: 合意形成 | I8: 横断・補足（個別対応は対応表） | J8: 46303 | K8: 46304 | L8: 0.5 | M8: 1.01 | N8: SE（氏名未定） | O8: 評価責任者・セキュリティ担当 | P8: 未着手 | Q8: I01,I03 | R8: 計画・評価・運用 | T8: 変更 | U8: 評価対象範囲・案分方針・会社名コードの確認を追加（工数据置）
A9: 1.04 | B9: 1. 評価準備・環境構築 | C9: 契約・機能 | D9: ライセンス・機能適用範囲確認 | E9: CEU、Workspace、追加ライセンスの有無を確認する。DLP、Context-Aware Access、監査・調査機能を機能別に照合する。Driveのランサムウェア検知・ファイル復元は、対応エディション、Drive for desktop前提の範囲、ChromeOSでの適用有無を確認する。 | F9: 必要機能・契約差分・試用期限が整理され、未契約と対象外を混同していない。Driveランサムウェア検知の適用範囲（ChromeOSの扱い）が明記されている。 | G9: 機能・ライセンス対応表（Drive勒索検知を含む） | H9: 仕様確認 | I9: 横断・補足（個別対応は対応表） | J9: 46303 | K9: 46304 | L9: 0.5 | M9: 1.01 | N9: SE（氏名未定） | O9: 契約担当・販売店 | P9: 未着手 | Q9: G02,G07,G14,G18,G19 | R9: 仕様確認中心 | T9: 変更 | U9: Driveランサムウェア検知・ファイル復元の対応版・適用範囲を確認項目に追加（工数据置）
A10: 1.05 | B10: 1. 評価準備・環境構築 | C10: 試験計画 | D10: 試験ケース・証跡ルール作成 | E10: 各WBSから試験IDを採番し、前提、操作、期待結果、実結果、判定、実施者を定義する。証跡に日時・端末・ユーザー・OU・ポリシー値を含める。 | F10: 試験を再現でき、評価枝番号から証跡を追跡できる。 | G10: 試験項目書・証跡命名規則 | H10: 設計確認 | I10: 横断・補足（個別対応は対応表） | J10: 46304 | K10: 46309 | L10: 0.5 | M10: 1.02,1.03,1.04 | N10: SE（氏名未定） | O10: セキュリティ担当 | P10: 未着手 | Q10: I01,G03,G04 | R10: 計画・評価・運用 | T10: 日程変更 | U10: 区間容量検査を満たすよう作業窓を調整（旧10/09～10/13）
A11: 1.06 | B11: 1. 評価準備・環境構築 | C11: 環境準備 | D11: テナント・OU・試験アカウント準備 | E11: 1.04と並行して既存の利用可能環境を確認し、試験OU・一般／管理／組織外アカウント・無害な試験データを準備する。1.09でネットワーク申請も開始する。 | F11: 必要な権限・アカウント・ネットワークが利用可能。 | G11: 試験環境一覧 | H11: 環境構築 | I11: 横断・補足（個別対応は対応表） | J11: 46303 | K11: 46308 | L11: 0.5 | M11: 1.01（1.04と並行） | N11: SE（氏名未定） | O11: Workspace管理者 | P11: 未着手 | Q11: G01,G02 | R11: 計画・評価・運用 | T11: 日程変更 | U11: 依存を「1.01（1.04と並行）」に修正（v2は1.04終了前に開始する矛盾）
A12: 1.07 | B12: 1. 評価準備・環境構築 | C12: 環境準備 | D12: 企業登録・資産登録 | E12: 機種、シリアル、OS、更新期限を記録し企業登録する。管理コンソールでOU・状態を確認し、Wi-Fiと基本ポリシーを配布する。 | F12: 対象機が管理対象となり、資産情報とポリシー適用が確認できる。 | G12: 端末台帳・登録記録 | H12: 実機試験 | I12: 横断・補足（個別対応は対応表） | J12: 46309 | K12: 46309 | L12: 0.5 | M12: 1.06,1.10 | N12: SE（氏名未定） | O12: 端末管理者 | P12: 未着手 | Q12: G01,G03,G10 | R12: 実機検証 | T12: 維持
A13: 1.08 | B13: 1. 評価準備・環境構築 | C13: 環境準備 | D13: ポリシー基線・反映確認 | E13: 承認した設定値を保存する。chrome://policy等で実効値を確認し、OU継承、再ログイン・再起動、反映時間を記録する。 | F13: 管理画面の設定と端末の実効値が一致し、反映条件が記録されている。 | G13: 設定基線・ポリシー出力 | H13: 実機試験 | I13: 32, 33, 34, 35 | J13: 46310 | K13: 46310 | L13: 0.5 | M13: 1.07 | N13: SE（氏名未定） | O13: 端末管理者 | P13: 未着手 | Q13: G03,G04 | R13: 実機検証 | T13: 日程変更 | U13: 区間容量検査を満たすよう作業窓を調整（旧10/14～10/14）
A14: 1.09 | B14: 1. 評価準備・環境構築 | C14: 接続準備 | D14: 接続要件・申請・リードタイム確認 | E14: Workspace登録・更新・VDI等の宛先、Proxy許可リスト、Wi-Fi認証、企業ルート証明書、端末証明書の配布方法を担当へ確認する。必要申請と回答期限を合意する。 | F14: 依頼先・申請内容・回答期限と接続完了条件が明確。待ち時間は作業工数と分けて追跡する。 | G14: 接続要件・申請台帳 | H14: 調整・既存設計確認 | I14: 横断・補足（個別対応は対応表） | J14: 46303 | K14: 46308 | L14: 0.5 | M14: 1.01 | N14: SE（氏名未定） | O14: ネットワーク・VDI・証明書管理者 | P14: 未着手 | Q14: G01,G03,G04 | R14: 接続申請・調整 | T14: 維持
A15: 1.10 | B15: 1. 評価準備・環境構築 | C15: 接続準備 | D15: 登録用ネットワーク・証明書の基本確認 | E15: 承認済み接続方式で登録に必要な通信を確立する。証明書・Proxyが登録前に必要な場合の初期設定経路を確認し、管理通信と更新通信を確認する。 | F15: 企業登録できる接続経路があり、証明書警告を無視せず通信できる。 | G15: 初期接続・証明書確認記録 | H15: 実機試験 | I15: 横断・補足（個別対応は対応表） | J15: 46308 | K15: 46309 | L15: 0.25 | M15: 1.06,1.09 | N15: SE（氏名未定） | O15: ネットワーク・証明書管理者 | P15: 未着手 | Q15: G01,G03 | R15: 基本接続の実機確認 | T15: 日程変更 | U15: 区間容量検査を満たすよう作業窓を調整（旧10/13～10/13）
A16: 1.11 | B16: 1. 評価準備・環境構築 | C16: 接続準備 | D16: VDI・M365・業務サービスの基本接続 | E16: 企業登録後、利用予定の業務サービス・VDIに試験アカウントで接続する。認証・画面表示・必須業務操作を確認し、通信不備は直ちに担当へ依頼する。あわせて業務アプリ互換チェックリスト（主要業務アプリ、周辺機器、印刷、ビデオ会議）を作成し、業務部門に実施を依頼して結果を回収する。 | F16: 主要サービスの基本利用可否が判明し、阻害要因を早期に課題化できる。業務アプリ互換の結果が6.05の業務影響に使える形で整理されている。正式制御試験は4.03で実施する。 | G16: 業務接続確認・接続課題一覧・業務アプリ互換チェックリスト | H16: 実機試験 | I16: 横断・補足（個別対応は対応表） | J16: 46310 | K16: 46311 | L16: 0.65 | M16: 1.07,1.10 | N16: SE（氏名未定） | O16: VDI・M365・業務システム担当・業務部門 | P16: 未着手 | Q16: I01,G01,C02 | R16: 基本接続の実機確認 | T16: 変更 | U16: 業務アプリ互換チェックリスト（業務部門が実施・SEは作成と回収）を追加（+0.15）
A17: 2.01 | B17: 2. 認証・権限管理 | C17: 認証・アカウント | D17: 会社アカウント以外の端末ログイン制限 | E17: 許可リストを設定し、会社・個人Gmail・他組織アカウントでログインする。許可・拒否の両方を確認する。 | F17: 承認済み会社アカウントのみ端末へログインできる。 | G17: 認証試験記録 | H17: 実機試験 | I17: 横断・補足（個別対応は対応表） | J17: 46311 | K17: 46311 | L17: 0.25 | M17: 1.08 | N17: SE（氏名未定） | O17: Workspace管理者 | P17: 未着手 | Q17: G03 | R17: 実機検証 | T17: 日程変更 | U17: 区間容量検査を満たすよう作業窓を調整（旧10/15～10/15）
A18: 2.02 | B18: 2. 認証・権限管理 | C18: 認証・アカウント | D18: 追加アカウント・マルチログイン制限 | E18: 端末ログイン後の個人アカウント追加と、複数ユーザー同時ログインを別々に試す。Webサービス内の個人アカウント利用も確認する。 | F18: 承認済みアカウント範囲を各経路で維持できる。制御対象外経路は記録する。 | G18: 追加ログイン試験記録 | H18: 実機試験 | I18: 横断・補足（個別対応は対応表） | J18: 46311 | K18: 46311 | L18: 0.25 | M18: 2.01 | N18: SE（氏名未定） | O18: Workspace管理者 | P18: 未着手 | Q18: G04,G05 | R18: 実機検証 | T18: 日程変更 | U18: 区間容量検査を満たすよう作業窓を調整（旧10/15～10/15）
A19: 2.03 | B19: 2. 認証・権限管理 | C19: 認証・アカウント | D19: MFA・フィッシング耐性評価 | E19: オンライン再認証で第2要素の成功・拒否・未登録を確認する。採用する認証方式のフィッシング耐性と復旧手順を評価する。パスキーやセキュリティキーなどフィッシング耐性のある方式の可否と、登録・失効手順も確認する。 | F19: 対象サービスで承認方式が強制され、例外・復旧経路が管理されている。 | G19: MFA設定・認証記録・例外一覧 | H19: 実機・仕様確認 | I19: 72, 73, 74, 164 | J19: 46311 | K19: 46314 | L19: 0.5 | M19: 1.03,2.01 | N19: SE（氏名未定） | O19: IdP管理者 | P19: 未着手 | Q19: I01,G03 | R19: 仕様確認中心 | T19: 変更 | U19: パスキー／セキュリティキーの可否・登録・失効手順を追加（工数据置）
A20: 2.04 | B20: 2. 認証・権限管理 | C20: 認証・アカウント | D20: 離線ログイン・画面ロック | E20: オンライン認証、キャッシュによる離線ログイン、PIN等のロック解除を区別して試す。無操作・スリープ復帰時のロックを測定する。最大セッション時間と強制オンライン再認証の頻度も確認する。 | F20: 承認したロック時間・離線利用条件・セッション上限を満たす。毎回のオンラインMFAと混同しない。 | G20: 離線・ロック試験記録 | H20: 実機試験 | I20: 横断・補足（個別対応は対応表） | J20: 46314 | K20: 46314 | L20: 0.25 | M20: 2.03 | N20: SE（氏名未定） | O20: 端末管理者 | P20: 未着手 | Q20: G03,G04,I03,C02 | R20: 実機検証 | T20: 変更 | U20: 最大セッション時間・強制オンライン再認証の頻度を追加（工数据置）
A21: 2.05 | B21: 2. 認証・権限管理 | C21: 認証情報保護 | D21: パスワード・保存・認証失敗対策 | E21: パスワード要件、ブラウザ保存、承認済み管理ツールを確認する。漏えい資格情報の検知とパスワード再利用警告（Password Alert）の可否を確認する。少数の試験用失敗ログインで記録・防御仕様を確認する。 | F21: 元要件との差分が整理される。固定回数ロックが非対応の場合は代替策を承認する。 | G21: 認証情報保護確認表 | H21: 実機・仕様確認 | I21: 78, 75, 81, 82, 86, 83, 84, 85 | J21: 46314 | K21: 46314 | L21: 0.5 | M21: 1.03,2.03 | N21: SE（氏名未定） | O21: IdP管理者・SOC | P21: 未着手 | Q21: I01,G04,G06,C02 | R21: 仕様確認中心 | T21: 変更 | U21: 漏えい資格情報検知・Password Alertの可否を追加（工数据置）
A22: 2.06 | B22: 2. 認証・権限管理 | C22: 権限管理 | D22: 一般権限と管理者権限の分離 | E22: 一般アカウントで管理操作を試し拒否を確認する。管理者ロールの範囲、専用管理アカウント、委託先権限を確認する。管理コンソール自体の保護として、スーパー管理者の人数と緊急用（break-glass）アカウント、管理者へのセキュリティキー必須化、管理コンソールを管理端末からのみ利用させる制御、復旧オプションとバックアップコードを確認する。 | F22: 必要最小限の権限のみ付与され、管理用と日常用アカウントが分離されている。管理コンソールの保護方式と緊急時の入口が記録されている。 | G22: 権限一覧・権限試験記録・管理コンソール保護確認表 | H22: 実機・運用確認 | I22: 76, 80, 92, 129, 124, 79 | J22: 46314 | K22: 46315 | L22: 0.75 | M22: 1.06 | N22: SE（氏名未定） | O22: Workspace管理者・委託先管理担当 | P22: 未着手 | Q22: I01,G15,C02 | R22: 実機検証 | T22: 変更 | U22: 管理コンソール自体の保護（break-glass、セキュリティキー、管理端末限定）を追加（+0.25）
A23: 2.07 | B23: 2. 認証・権限管理 | C23: アカウント運用 | D23: 停用・権限棚卸し・セッション処置 | E23: 試験ユーザーを停止し、新規ログインと既存セッションを確認する。OAuth許可・セッション失効、退職処理、四半期棚卸し手順も確認する。 | F23: 停止後のアクセス制限範囲と反映時間が記録され、離線時の残存リスクが明示される。 | G23: 停用試験・棚卸し手順 | H23: 実機・運用確認 | I23: 132, 128 | J23: 46315 | K23: 46316 | L23: 0.5 | M23: 2.06 | N23: SE（氏名未定） | O23: IdP管理者・人事窓口 | P23: 未着手 | Q23: I01,G08 | R23: 実機検証 | T23: 日程変更 | U23: 区間容量検査を満たすよう作業窓を調整（旧10/20～10/20）
A24: 3.01 | B24: 3. 端末・アプリ・更新管理 | C24: 端末保護 | D24: ゲスト・開発者モード・Linux環境制限 | E24: ゲスト経路を確認する。強制再登録の設定と開発者モード制限を検証する。Linux開発環境、Androidデバッグの許可範囲を別途確認する。DevTools、chrome://flags、Crosh、管理ゲストセッションの可否も確認する。 | F24: 未承認の利用・実行環境を開けない。設定名称と端末の挙動を保存する。 | G24: ハードニング試験記録 | H24: 実機試験 | I24: 横断・補足（個別対応は対応表） | J24: 46316 | K24: 46316 | L24: 0.4 | M24: 1.08 | N24: SE（氏名未定） | O24: 端末管理者 | P24: 未着手 | Q24: G03,G04,G09,C02,C04 | R24: 実機検証 | T24: 変更 | U24: DevTools・chrome://flags・Crosh・管理ゲストセッションの可否を追加（+0.15）
A25: 3.02 | B25: 3. 端末・アプリ・更新管理 | C25: 端末保護 | D25: 標準保護仕様・実効設定・ユーザー分離 | E25: Google公式仕様でVerified Boot、サンドボックス、暗号化の対象を確認する。3.01の実効設定を引用し、一般ユーザー間で保存したダミーファイルが見えないことを確認する。exe試験は原則省略する。 | F25: 仕様上の保護と実機確認を区別して記録。Linux禁止を全スクリプト実行不可の証明にしない。 | G25: 仕様根拠・設定証跡・分離確認記録 | H25: 仕様＋限定実機 | I25: 114, 115 | J25: 46316 | K25: 46316 | L25: 0.25 | M25: 3.01 | N25: SE（氏名未定） | O25: セキュリティ担当 | P25: 未着手 | Q25: G11,I01 | R25: 仕様確認中心 | T25: 維持
A26: 3.03 | B26: 3. 端末・アプリ・更新管理 | C26: アプリ管理 | D26: 拡張機能の許可・拒否・強制配布 | E26: 未許可拡張の導入を試す。許可した拡張の導入、強制配布、削除制限を確認し、申請・承認・取消手順を作成する。PWA（Webアプリ）の導入可否と、未承認のリモートアクセス系拡張・Chrome Remote Desktopのホスト／クライアント制限を確認する。 | F26: 承認済み拡張・Webアプリのみ利用でき、例外と変更が追跡できる。リモートアクセス系ツールの利用範囲が管理されている。 | G26: 拡張機能・PWA試験・承認一覧 | H26: 実機試験 | I26: 104, 106, 125, 26 | J26: 46316 | K26: 46317 | L26: 0.45 | M26: 1.08 | N26: SE（氏名未定） | O26: Workspace管理者 | P26: 未着手 | Q26: G04,C02,C03 | R26: 実機検証 | T26: 変更 | U26: PWA・リモートアクセス系ツール（拡張・Chrome Remote Desktop）の制御を追加（+0.20）
A27: 3.04 | B27: 3. 端末・アプリ・更新管理 | C27: アプリ管理 | D27: Androidアプリ・APK経路確認 | E27: Android利用の要否を決め、禁止または許可リストを適用する。未許可アプリ、外部APK導入経路、デバッグ利用を確認する。未承認のリモートアクセス系Androidアプリの導入可否も確認する。 | F27: 承認した配布経路のみ利用できる。機種非対応なら仕様と理由を記録する。 | G27: Android試験記録 | H27: 実機・仕様確認 | I27: 横断・補足（個別対応は対応表） | J27: 46317 | K27: 46317 | L27: 0.25 | M27: 3.01,3.03 | N27: SE（氏名未定） | O27: 端末管理者 | P27: 未着手 | Q27: G04 | R27: 仕様確認中心 | T27: 変更 | U27: 未承認のリモートアクセス系Androidアプリの導入可否を追加（工数据置）
A28: 3.05 | B28: 3. 端末・アプリ・更新管理 | C28: アプリ管理 | D28: OAuthアプリ・API権限管理 | E28: 承認済み試験アプリと未承認アプリへのデータアクセスを確認する。要求スコープ、既存同意、許可取消を確認する。 | F28: 承認範囲を超えるデータアクセスを制御でき、許可取消の結果が記録される。 | G28: OAuth設定・認可試験記録 | H28: 実機試験 | I28: 140 | J28: 46317 | K28: 46317 | L28: 0.5 | M28: 1.04,2.06 | N28: SE（氏名未定） | O28: Workspace管理者 | P28: 未着手 | Q28: G08 | R28: 実機検証 | T28: 維持
A29: 3.06 | B29: 3. 端末・アプリ・更新管理 | C29: 更新・脆弱性 | D29: 自動更新・再起動・最低バージョン | E29: 利用可能な更新を用いて更新前後を記録し、再起動と最低バージョンの期限動作を確認する。更新が無い場合は実更新を未検証とする。 | F29: 設定確認と実更新を区別し、期限・ユーザー回避可否を評価できる。 | G29: 更新試験・バージョン記録 | H29: 実機試験 | I29: 横断・補足（個別対応は対応表） | J29: 46318 | K29: 46321 | L29: 0.5 | M29: 1.07,1.03 | N29: SE（氏名未定） | O29: 端末管理者 | P29: 未着手 | Q29: G03,G10 | R29: 実機検証 | T29: 維持
A30: 3.07 | B30: 3. 端末・アプリ・更新管理 | C30: 更新・脆弱性 | D30: 脆弱性情報・AUE・更新失敗運用 | E30: 対象機種の更新期限、脆弱性情報の収集元、適用期限、オフライン・更新失敗・期限切れ端末の扱いを定める。 | F30: 検出から対処までの担当・期限・代替策が定義されている。 | G30: 更新運用手順・例外台帳 | H30: 仕様・運用確認 | I30: 28, 29, 30, 31, 49, 50, 51 | J30: 46318 | K30: 46321 | L30: 0.25 | M30: 1.07（3.06と並行） | N30: SE（氏名未定） | O30: セキュリティ担当 | P30: 未着手 | Q30: G10,I01 | R30: 仕様確認中心 | T30: 日程変更 | U30: 依存を「1.07（3.06と並行）」に修正（v2は3.06終了前に開始する矛盾）
A31: 3.08 | B31: 3. 端末・アプリ・更新管理 | C31: 資産・構成管理 | D31: 資産・アプリ台帳と構成差分 | E31: デバイス・アプリ情報を台帳と照合する。試験OUの設定を変更し、基線との差分、変更ログ、復元を確認する。 | F31: 所有者・重要度・依存関係が台帳にあり、設定差分を検出・修正できる。 | G31: 資産台帳・構成差分・変更記録 | H31: 実機・運用確認 | I31: 119, 120, 121, 122, 39, 40, 123, 41 | J31: 46321 | K31: 46321 | L31: 0.25 | M31: 1.08,3.03 | N31: SE（氏名未定） | O31: 資産管理担当 | P31: 未着手 | Q31: I01,G03,G04 | R31: 実機検証 | T31: 維持
A32: 3.09 | B32: 3. 端末・アプリ・更新管理 | C32: 防御範囲評価 | D32: 標準機能とAV／EDR要件の差分確認 | E32: 公式アーキテクチャ資料と既存のセキュリティ対策を用い、予防・検知・隔離・取証のカバー範囲を整理する。実マルウェアや検出率試験は行わない。未カバー部分は代替策を提示する。 | F32: 原要件、仕様根拠、未カバー能力、既存対策、残余リスクを示し、安全評価責任者に受容可否を確認する。 | G32: AV／EDR適合性・代替策評価表 | H32: 仕様・既存証跡 | I32: 102, 103, 107, 174, 108, 109, 172, 173 | J32: 46321 | K32: 46322 | L32: 0.5 | M32: 3.02,3.03 | N32: SE（氏名未定） | O32: セキュリティ担当・SOC | P32: 未着手 | Q32: I01,G11 | R32: 既存証跡を活用 | T32: 維持
A33: 4.01 | B33: 4. 通信・データ保護 | C33: Web保護 | D33: Safe Browsing・ダウンロード制御 | E33: 無害な公式テストページ等で警告・ブロックを確認する。ユーザーによる回避、許可ファイルの業務影響を記録する。証明書エラーの上書き可否、Safe Browsingの強化モードと警告回避禁止の設定も確認する。 | F33: 承認済みポリシーが強制され、警告と遮断を区別して記録できる。 | G33: Web保護試験記録 | H33: 実機試験 | I33: 178 | J33: 46322 | K33: 46322 | L33: 0.25 | M33: 1.08 | N33: SE（氏名未定） | O33: セキュリティ担当 | P33: 未着手 | Q33: G04,G06,C02 | R33: 実機検証 | T33: 変更 | U33: 証明書エラー上書き・Safe Browsing強化モード・警告回避禁止を追加（工数据置）
A34: 4.02 | B34: 4. 通信・データ保護 | C34: Web保護 | D34: URL・サイト権限・情報送信制御 | E34: 安全な試験URLで許可／拒否を確認する。通知、追跡関連設定、入力補完・診断情報等の送信先と必要性を確認する。ChromeOSの生成AI機能（Gemini等）の可否と外部送信を確認する。原票のTracking prevention／Website typo protectionはEdgeの機能名のため、Chrome／ChromeOSでの同等機能の有無を確認し、無ければ代替策を記録する。 | F34: 業務アクセスを維持しつつ、不要なサイト権限・情報送信が制御される。同等機能が無い項目は「直接の同等機能なし＋代替策」と記録し、満たしたとは扱わない。 | G34: URL・ブラウザ設定確認表 | H34: 実機・仕様確認 | I34: 177, 179, 176 | J34: 46322 | K34: 46322 | L34: 0.25 | M34: 4.01 | N34: SE（氏名未定） | O34: セキュリティ担当 | P34: 未着手 | Q34: G04,G06,C03,G21 | R34: 仕様確認中心 | T34: 変更 | U34: 生成AI機能の可否・Edge固有機能の扱いを追加（工数据置）
A35: 4.03 | B35: 4. 通信・データ保護 | C35: ネットワーク | D35: 通信経路・利用者変更・制御迂回の検証 | E35: 1.09～1.11で打通済みの会社／外部ネットワークで、承認済みVPN・Proxy・DNS経路と許可／拒否を確認する。利用者が設定を変更して制御を回避できないか確認する。 | F35: 基本疎通とは別に通信制御の有効性を記録し、制御できない経路は残余リスクとして記載する。 | G35: ネットワーク試験・データフロー | H35: 実機試験 | I35: 52, 53, 113, 144, 145, 96, 27 | J35: 46318 | K35: 46321 | L35: 0.5 | M35: 1.10,1.11 | N35: SE（氏名未定） | O35: ネットワーク担当 | P35: 未着手 | Q35: I01,G03,G04 | R35: 実機検証 | T35: 日程変更 | U35: 区間容量検査を満たすよう作業窓を調整（旧10/23～10/23）
A36: 4.04a | B36: 4. 通信・データ保護 | C36: 接続先管理 | D36: 接続先証跡確認（AD／DC／Windows管理・27項目） | E36: AD管理者から、ドメインコントローラー（原票の「データセンター」は原文のDC＝Domain Controllerの訳）、特権アカウント、PowerShell／スクリプト、LSASS・資格情報保護等の設定証跡を受領する（27項目）。サーバー側の再試験は原則行わず、Chromebook導入で変わる経路のみ1.11の結果を参照して補足確認する。 | F36: 端末側と接続先の評価責任・証跡が明確。既存証跡不足や新規経路は課題として担当へ引き継ぎ、回答期限と状況を追跡できる。 | G36: 接続先評価・依存関係一覧（AD／Windows） | H36: 既存証跡＋差分確認 | I36: 87, 88, 89, 101, 130, 131, 146, 147, 148, 149, 150, 151, 152, 153, 154, 155, 156, 157, 158, 159, 160, 161, 162, 168, 196, 202, 203 | J36: 46310 | K36: 46323 | L36: 0.2 | M36: 1.02 | N36: SE（氏名未定） | O36: AD／Windows管理者 | P36: 未着手 | Q36: I01 | R36: 既存証跡を活用 | T36: 分割 | U36: 旧4.04（68項目・0.50人日）を責任者別に分割。回答期限と状態を個別に追跡
A37: 4.04b | B37: 4. 通信・データ保護 | C37: 接続先管理 | D37: 接続先証跡確認（SMB／NTLM／暗号化・22項目） | E37: ファイルサーバー管理者から、SMBの版数・署名・暗号化、NTLM制限、NetBIOS関連の設定証跡を受領する（22項目）。Chromebook側のSMB／NTLMクライアント制御は4.09で確認する。 | F37: 端末側と接続先の評価責任・証跡が明確。既存証跡不足や新規経路は課題として担当へ引き継ぎ、回答期限と状況を追跡できる。 | G37: 接続先評価・依存関係一覧（SMB／NTLM／暗号化） | H37: 既存証跡＋差分確認 | I37: 54, 55, 56, 57, 58, 59, 60, 61, 62, 63, 64, 65, 66, 67, 68, 69, 70, 71, 163, 165, 166, 167 | J37: 46310 | K37: 46323 | L37: 0.15 | M37: 1.02 | N37: SE（氏名未定） | O37: ファイルサーバー・ストレージ管理者 | P37: 未着手 | Q37: I01 | R37: 既存証跡を活用 | T37: 分割 | U37: 旧4.04（68項目・0.50人日）を責任者別に分割。回答期限と状態を個別に追跡
A38: 4.04c | B38: 4. 通信・データ保護 | C38: 接続先管理 | D38: 接続先証跡確認（VDI／RDP／リモート／RMM・14項目） | E38: VDI・リモートアクセス基盤の担当者から、RDP・リモート環境・RMM・公開サービス・不要機能の設定証跡を受領する（14項目）。端末側のリモートアクセス系ツールの制御は3.03／3.04で確認する。 | F38: 端末側と接続先の評価責任・証跡が明確。既存証跡不足や新規経路は課題として担当へ引き継ぎ、回答期限と状況を追跡できる。 | G38: 接続先評価・依存関係一覧（VDI／RDP／リモート／RMM） | H38: 既存証跡＋差分確認 | I38: 24, 25, 38, 42, 43, 44, 45, 46, 47, 48, 91, 141, 142, 223 | J38: 46310 | K38: 46323 | L38: 0.1 | M38: 1.02 | N38: SE（氏名未定） | O38: VDI・リモートアクセス基盤担当 | P38: 未着手 | Q38: I01 | R38: 既存証跡を活用 | T38: 分割 | U38: 旧4.04（68項目・0.50人日）を責任者別に分割。回答期限と状態を個別に追跡
A39: 4.04d | B39: 4. 通信・データ保護 | C39: 接続先管理 | D39: 接続先証跡確認（仮想化・アプリ制御・ログ等・5項目） | E39: 仮想化基盤、アプリケーション制御、アンチマルウェア運用、ツール使用調査、認証イベントログの既存証跡を担当者から受領し、ChromeOSで変わる点のみ補足する（5項目）。 | F39: 端末側と接続先の評価責任・証跡が明確。既存証跡不足や新規経路は課題として担当へ引き継ぎ、回答期限と状況を追跡できる。 | G39: 接続先評価・依存関係一覧（仮想化・アプリ制御・ログ等） | H39: 既存証跡＋差分確認 | I39: 105, 110, 133, 199, 224 | J39: 46310 | K39: 46323 | L39: 0.05 | M39: 1.02 | N39: SE（氏名未定） | O39: 仮想化基盤・セキュリティ運用担当 | P39: 未着手 | Q39: I01 | R39: 既存証跡を活用 | T39: 分割 | U39: 旧4.04（68項目・0.50人日）を責任者別に分割。回答期限と状態を個別に追跡
A40: 4.05 | B40: 4. 通信・データ保護 | C40: データ持出し | D40: USB・外部記憶媒体制限 | E40: 会社方針の禁止または読取専用を設定し、試験ファイルの読込・書込・削除を試す。利用する媒体種別ごとに確認する。 | F40: 対象媒体で承認設定が効き、許可する周辺機器への影響も記録される。 | G40: USB試験記録 | H40: 実機試験 | I40: 横断・補足（個別対応は対応表） | J40: 46324 | K40: 46324 | L40: 0.25 | M40: 1.08 | N40: SE（氏名未定） | O40: 端末管理者 | P40: 未着手 | Q40: G04,I03 | R40: 実機検証 | T40: 維持
A41: 4.06 | B41: 4. 通信・データ保護 | C41: データ持出し | D41: 外部共有・印刷・コピー・ダウンロード | E41: 試験データで外部ユーザー共有、リンク共有、印刷、コピー、ダウンロードを経路別に確認する。所有者／閲覧者権限を区別する。 | F41: 会社方針に対する可否と制御範囲が記録され、未対応経路が残余リスクに挙がる。 | G41: データ持出し試験・例外一覧 | H41: 実機試験 | I41: 横断・補足（個別対応は対応表） | J41: 46324 | K41: 46324 | L41: 0.5 | M41: 1.04,2.02 | N41: SE（氏名未定） | O41: データ所有部門・Workspace管理者 | P41: 未着手 | Q41: G04,G07,I03 | R41: 実機検証 | T41: 維持
...

Sheet 評価項目対応
A2: 評価項目と作業の対応（231項目）
A3: 全行は評価作業の割当案。原票O～Xへの転記前に適用性と根拠を確認し、必要な関連WBSも参照する。v3で主対応WBSを4.04a～d・5.07a・5.06へ再配分し、関連WBS（副）と担当部署／回答責任者／回答者（原票V～X）の列を追加した。黄色セルが入力欄。
A5: 原票行 | B5: 枝番号 | C5: CPG ID | D5: 原票チェック観点 | E5: 原票チェック内容 | F5: 主対応WBS | G5: 評価方法（案） | H5: Chromebookでの確認方針（案） | I5: 適用性（確認用） | J5: 担当部署（原票V列） | K5: 証跡・試験ID | L5: 判断理由・未解決事項 | M5: 関連WBS（副） | N5: 回答責任者（原票W列） | O5: 回答者（原票X列） | P5: 担当役割（候補・主対応WBSの協力先）
A6: 3 | B6: 119 | C6: 1.A | D6: 資産管理と構成管理 | E6: 組織が包括的な資産管理アプローチを持っていることを確認する。 | F6: 3.08 | G6: 実機・運用確認 | H6: 端末登録に加え、アプリ・データ・重要業務・依存関係・台帳保護を確認する。 | I6: 未確定 | P6: =IFERROR(INDEX(WBS!$O$6:$O$59,MATCH($F6,WBS!$A$6:$A$59,0)),"") -> 資産管理担当
A7: 4 | B7: 120 | C7: 1.A | D7: 資産管理と構成管理 | E7: 組織のITアセット、論理的（データ、ソフトウェアなど）および物理的（ ハードウェアなど）の在庫を把握する。 | F7: 3.08 | G7: 実機・運用確認 | H7: 端末登録に加え、アプリ・データ・重要業務・依存関係・台帳保護を確認する。 | I7: 未確定 | P7: =IFERROR(INDEX(WBS!$O$6:$O$59,MATCH($F7,WBS!$A$6:$A$59,0)),"") -> 資産管理担当
A8: 5 | B8: 121 | C8: 1.A | D8: 資産管理と構成管理 | E8: 健康と安全、収益創出、またはその他の重要なサービスにとって最も重要 なデータまたはシステムを把握し、関連する相互依存関係を理解する。 | F8: 3.08 | G8: 実機・運用確認 | H8: 重要業務・データ・接続先の依存関係と復旧優先順位を整理する。企業登録のみでは本項目を満たさない。 | I8: 未確定 | P8: =IFERROR(INDEX(WBS!$O$6:$O$59,MATCH($F8,WBS!$A$6:$A$59,0)),"") -> 資産管理担当
A9: 6 | B9: 122 | C9: 1.A | D9: 資産管理と構成管理 | E9: セキュリティ制御または保護措置をクリティカルアセットに適用する。 | F9: 3.08 | G9: 実機・運用確認 | H9: 端末登録に加え、アプリ・データ・重要業務・依存関係・台帳保護を確認する。 | I9: 未確定 | P9: =IFERROR(INDEX(WBS!$O$6:$O$59,MATCH($F9,WBS!$A$6:$A$59,0)),"") -> 資産管理担当
A10: 7 | B10: 153 | C10: 1.E | D10: データセンター管理 | E10: データセンターが定期的にパッチが適用されていることを確認する。重大 な脆弱性のパッチは、できるだけ早く適用する。 | F10: 4.04a | G10: 既存証跡・境界確認 | H10: 原票の「データセンター」表記は原文のDC（Domain Controller）の訳。ADドメインコントローラーの設定・パッチ・監視の既存証跡を担当者から受領する。ChromeOS利用だけで対象外にしない。 | I10: 未確定 | P10: =IFERROR(INDEX(WBS!$O$6:$O$59,MATCH($F10,WBS!$A$6:$A$59,0)),"") -> AD／Windows管理者
A11: 8 | B11: 36 | C11: 1.E | D11: IaCの利用と管理 | E11: IaCテンプレートを展開する前に、静的セキュリティスキャンツールでテ ストする。 | F11: 1.02 | G11: 構成依存の確認 | H11: IaC利用の有無を関連クラウドも含めて確認する。未使用なら範囲と理由を記載する。 | I11: 未確定 | P11: =IFERROR(INDEX(WBS!$O$6:$O$59,MATCH($F11,WBS!$A$6:$A$59,0)),"") -> 各システム管理者・セキュリティ担当
A12: 9 | B12: 37 | C12: 1.E | D12: IaCの利用と管理 | E12: 静的セキュリティスキャンツールで設定ミスとセキュリティギャップを特 定する。 | F12: 1.02 | G12: 構成依存の確認 | H12: IaC利用の有無を関連クラウドも含めて確認する。未使用なら範囲と理由を記載する。 | I12: 未確定 | P12: =IFERROR(INDEX(WBS!$O$6:$O$59,MATCH($F12,WBS!$A$6:$A$59,0)),"") -> 各システム管理者・セキュリティ担当
A13: 10 | B13: 4 | C13: 1.E | D13: IaCの利用と管理 | E13: インフラストラクチャをコード（IaC）を使用してクラウドリソースを展 開および更新する。 | F13: 1.02 | G13: 構成依存の確認 | H13: IaC利用の有無を関連クラウドも含めて確認する。未使用なら範囲と理由を記載する。 | I13: 未確定 | P13: =IFERROR(INDEX(WBS!$O$6:$O$59,MATCH($F13,WBS!$A$6:$A$59,0)),"") -> 各システム管理者・セキュリティ担当
A14: 11 | B14: 5 | C14: 1.E | D14: IaCの利用と管理 | E14: IaCのテンプレートファイルのバックアップをオフラインで保管する。 | F14: 1.02 | G14: 構成依存の確認 | H14: IaC利用の有無を関連クラウドも含めて確認する。未使用なら範囲と理由を記載する。 | I14: 未確定 | P14: =IFERROR(INDEX(WBS!$O$6:$O$59,MATCH($F14,WBS!$A$6:$A$59,0)),"") -> 各システム管理者・セキュリティ担当
A15: 12 | B15: 6 | C15: 1.E | D15: IaCの利用と管理 | E15: ヒューマンエラーの削減のためのIaCコードはバージョン管理する。 | F15: 1.02 | G15: 構成依存の確認 | H15: IaC利用の有無を関連クラウドも含めて確認する。未使用なら範囲と理由を記載する。 | I15: 未確定 | P15: =IFERROR(INDEX(WBS!$O$6:$O$59,MATCH($F15,WBS!$A$6:$A$59,0)),"") -> 各システム管理者・セキュリティ担当
A16: 13 | B16: 7 | C16: 1.E | D16: IaCの利用と管理 | E16: IaCのテンプレートへの変更を監査する。 | F16: 1.02 | G16: 構成依存の確認 | H16: IaC利用の有無を関連クラウドも含めて確認する。未使用なら範囲と理由を記載する。 | I16: 未確定 | P16: =IFERROR(INDEX(WBS!$O$6:$O$59,MATCH($F16,WBS!$A$6:$A$59,0)),"") -> 各システム管理者・セキュリティ担当
A17: 14 | B17: 39 | C17: 1.E | D17: 構成ドリフトのチェッ ク | E17: テンプレート展開の外で変更または導入されたリソースを特定するために 、構成ドリフト（期待された状態からの乖離）を定期的にチェックする。 | F17: 3.08 | G17: 実機・運用確認 | H17: Google管理ポリシーの承認基線と実効値、変更履歴、差分検出・復元を確認する。 | I17: 未確定 | P17: =IFERROR(INDEX(WBS!$O$6:$O$59,MATCH($F17,WBS!$A$6:$A$59,0)),"") -> 資産管理担当
... A60: 57 | B60: 49 | C60: 2.G | D60: VPN管理 | E60: VPNを最新のソフトウェアパッチとセキュリティ設定で更新する。 | F60: 3.07 | G60: 仕様・運用確認 | H60: ChromeOSと接続先・ネットワーク製品を分けて脆弱性・更新運用を確認する。 | I60: 未確定 | P60: =IFERROR(INDEX(WBS!$O$6:$O$59,MATCH($F60,WBS!$A$6:$A$59,0)),"") -> セキュリティ担当
A61: 58 | B61: 83 | C61: 2.G | D61: アカウント管理 | E61: 一定回数のログイン失敗後にアカウントをロックアウトするポリシーを実 施する。 | F61: 2.05 | G61: 実機・仕様確認 | H61: 認証情報保護、保存制限、認証失敗監視を原要求と比較する。非対応機能は代替策と差分を記録する。 端末側のログ・上報（Chromeイベント、システムログ、端末上の失敗ログイン）の確認（5.03）も根拠にする。 | I61: 未確定 | M61: 5.03 | P61: =IFERROR(INDEX(WBS!$O$6:$O$59,MATCH($F61,WBS!$A$6:$A$59,0)),"") -> IdP管理者・SOC
A62: 59 | B62: 84 | C62: 2.G | D62: アカウント管理 | E62: ブルートフォースパスワードクラッキングとパスワードスプレーのための ログイン試行をログに記録し監視する。 | F62: 2.05 | G62: 実機・仕様確認 | H62: 認証情報保護、保存制限、認証失敗監視を原要求と比較する。非対応機能は代替策と差分を記録する。 端末側のログ・上報（Chromeイベント、システムログ、端末上の失敗ログイン）の確認（5.03）も根拠にする。 | I62: 未確定 | M62: 5.03 | P62: =IFERROR(INDEX(WBS!$O$6:$O$59,MATCH($F62,WBS!$A$6:$A$59,0)),"") -> IdP管理者・SOC
A63: 60 | B63: 50 | C63: 2.G | D63: ネットワーク管理 | E63: ネットワークインフラデバイスを最新のソフトウェアパッチとセキュリテ ィ設定で更新する。 | F63: 3.07 | G63: 仕様・運用確認 | H63: ChromeOSと接続先・ネットワーク製品を分けて脆弱性・更新運用を確認する。 | I63: 未確定 | P63: =IFERROR(INDEX(WBS!$O$6:$O$59,MATCH($F63,WBS!$A$6:$A$59,0)),"") -> セキュリティ担当
A64: 61 | B64: 51 | C64: 2.G | D64: リモート環境管理 | E64: リモートワーク環境へのアクセスに使用されるデバイスを最新のソフトウ ェアパッチとセキュリティ設定で更新する。 | F64: 3.07 | G64: 仕様・運用確認 | H64: ChromeOSと接続先・ネットワーク製品を分けて脆弱性・更新運用を確認する。 | I64: 未確定 | P64: =IFERROR(INDEX(WBS!$O$6:$O$59,MATCH($F64,WBS!$A$6:$A$59,0)),"") -> セキュリティ担当
A65: 62 | B65: 163 | C65: 2.G | D65: 認証管理 | E65: 可能であれば、NTLM と WDigest 認証を無効にするか制限することを検討 する。 （レガシーシステムのアップグレードやネットワークのセグメンテーショ ンの優先順位付けの基準としてそれらの使用を含める） | F65: 4.04b | G65: 既存証跡・境界確認 | H65: 接続先のSMB・NTLM・暗号化設定は既存証跡を受領する。ChromeOS側のSMBクライアント制御（共有マウント可否・NTLM・NetBIOS探索）は4.09で確認する。 本項目はChromebook側のSMB／NTLM／NetBIOS試験（4.09）も根拠にする。 | I65: 未確定 | M65: 4.09 | P65: =IFERROR(INDEX(WBS!$O$6:$O$59,MATCH($F65,WBS!$A$6:$A$59,0)),"") -> ファイルサーバー・ストレージ管理者
A66: 63 | B66: 165 | C66: 2.G | D66: 認証管理 | E66: NTLM を有効にする必要がある場合は、一部の NTLM リレー攻撃を防ぐた めに認証の拡張保護（EPA）を有効にする。 | F66: 4.04b | G66: 既存証跡・境界確認 | H66: 接続先のSMB・NTLM・暗号化設定は既存証跡を受領する。ChromeOS側のSMBクライアント制御（共有マウント可否・NTLM・NetBIOS探索）は4.09で確認する。 | I66: 未確定 | P66: =IFERROR(INDEX(WBS!$O$6:$O$59,MATCH($F66,WBS!$A$6:$A$59,0)),"") -> ファイルサーバー・ストレージ管理者
A67: 64 | B67: 166 | C67: 2.G | D67: 認証管理 | E67: ネットワーク全体で NTLMv2 応答のみが送信されるようにするために、NT LM 監査を有効にする。 | F67: 4.04b | G67: 既存証跡・境界確認 | H67: 接続先のSMB・NTLM・暗号化設定は既存証跡を受領する。ChromeOS側のSMBクライアント制御（共有マウント可否・NTLM・NetBIOS探索）は4.09で確認する。 | I67: 未確定 | P67: =IFERROR(INDEX(WBS!$O$6:$O$59,MATCH($F67,WBS!$A$6:$A$59,0)),"") -> ファイルサーバー・ストレージ管理者
A68: 65 | B68: 167 | C68: 2.G | D68: 認証管理 | E68: 可能であれば、LM および NTLM 応答が拒否されるように対策を講じる。 | F68: 4.04b | G68: 既存証跡・境界確認 | H68: 接続先のSMB・NTLM・暗号化設定は既存証跡を受領する。ChromeOS側のSMBクライアント制御（共有マウント可否・NTLM・NetBIOS探索）は4.09で確認する。 本項目はChromebook側のSMB／NTLM／NetBIOS試験（4.09）も根拠にする。 | I68: 未確定 | M68: 4.09 | P68: =IFERROR(INDEX(WBS!$O$6:$O$59,MATCH($F68,WBS!$A$6:$A$59,0)),"") -> ファイルサーバー・ストレージ管理者
A69: 66 | B69: 72 | C69: 2.H | D69: MFAの適用 | E69: すべてのサービスにフィッシング耐性のある多要素認証を実装する。 | F69: 2.03 | G69: 実機・仕様確認 | H69: 第2要素の有無だけでなく採用方式のフィッシング耐性を確認する。端末のPIN解除とオンラインMFAを区別する。 管理者のセキュリティキー必須化・管理コンソール保護（2.06）も根拠にする。 | I69: 未確定 | M69: 2.06 | P69: =IFERROR(INDEX(WBS!$O$6:$O$59,MATCH($F69,WBS!$A$6:$A$59,0)),"") -> IdP管理者
A70: 67 | B70: 73 | C70: 2.H | D70: MFAの適用 | E70: 多要素認証を許可しないシステム、多要素認証を強制しないシステム、多 要素認証に登録されていないユーザーを発見した場合、上級管理職にエス カレーションする。 | F70: 2.03 | G70: 実機・仕様確認 | H70: オンライン認証、抗フィッシング方式、未登録・例外の管理、復旧経路を確認する。 管理者のセキュリティキー必須化・管理コンソール保護（2.06）も根拠にする。 | I70: 未確定 | M70: 2.06 | P70: =IFERROR(INDEX(WBS!$O$6:$O$59,MATCH($F70,WBS!$A$6:$A$59,0)),"") -> IdP管理者
A71: 68 | B71: 74 | C71: 2.H | D71: MFAの適用 | E71: パスワードを2つ以上の検証要素（指紋、顔認識、デバイスのPIN、暗号鍵 など）に置き換えるパスワードレス多要素認証の採用を検討する。 | F71: 2.03 | G71: 実機・仕様確認 | H71: オンライン認証、抗フィッシング方式、未登録・例外の管理、復旧経路を確認する。 管理者のセキュリティキー必須化・管理コンソール保護（2.06）も根拠にする。 | I71: 未確定 | M71: 2.06 | P71: =IFERROR(INDEX(WBS!$O$6:$O$59,MATCH($F71,WBS!$A$6:$A$59,0)),"") -> IdP管理者
A72: 69 | B72: 42 | C72: 2.H | D72: RDPの管理 | E72: RDPやその他のリモートデスクトップサービスの使用を制限する。 | F72: 4.04c | G72: 既存証跡・境界確認 | H72: VDI・RDP・リモート環境・RMM・公開サービスの既存証跡を受領する。端末側のリモートアクセス系ツール（拡張・Android・Chrome Remote Desktop）の制御は3.03／3.04で確認する。 端末側のリモートアクセス系ツール（拡張・PWA・Androidアプリ・Chrome Remote Desktop）の制御（3.03／3.04）も根拠にする。 | I72: 未確定 | M72: 3.03, 3.04 | P72: =IFERROR(INDEX(WBS!$O$6:$O$59,MATCH($F72,WBS!$A$6:$A$59,0)),"") -> VDI・リモートアクセス基盤担当
A73: 70 | B73: 43 | C73: 2.H | D73: RDPの管理 | E73: RDPが必要な場合は、ベストプラクティスを適用する。 | F73: 4.04c | G73: 既存証跡・境界確認 | H73: VDI・RDP・リモート環境・RMM・公開サービスの既存証跡を受領する。端末側のリモートアクセス系ツール（拡張・Android・Chrome Remote Desktop）の制御は3.03／3.04で確認する。 | I73: 未確定 | P73: =IFERROR(INDEX(WBS!$O$6:$O$59,MATCH($F73,WBS!$A$6:$A$59,0)),"") -> VDI・リモートアクセス基盤担当
A74: 71 | B74: 44 | C74: 2.H | D74: RDPの管理 | E74: ネットワーク上でRDPを使用しているシステムを監査する。 | F74: 4.04c | G74: 既存証跡・境界確認 | H74: VDI・RDP・リモート環境・RMM・公開サービスの既存証跡を受領する。端末側のリモートアクセス系ツール（拡張・Android・Chrome Remote Desktop）の制御は3.03／3.04で確認する。 | I74: 未確定 | P74: =IFERROR(INDEX(WBS!$O$6:$O$59,MATCH($F74,WBS!$A$6:$A$59,0)),"") -> VDI・リモートアクセス基盤担当
A75: 72 | B75: 45 | C75: 2.H | D75: RDPの管理 | E75: 使用されていないRDPポートを閉じる。 | F75: 4.04c | G75: 既存証跡・境界確認 | H75: VDI・RDP・リモート環境・RMM・公開サービスの既存証跡を受領する。端末側のリモートアクセス系ツール（拡張・Android・Chrome Remote Desktop）の制御は3.03／3.04で確認する。 | I75: 未確定 | P75: =IFERROR(INDEX(WBS!$O$6:$O$59,MATCH($F75,WBS!$A$6:$A$59,0)),"") -> VDI・リモートアクセス基盤担当
A76: 73 | B76: 46 | C76: 2.H | D76: RDPの管理 | E76: 指定回数のログイン試行後にアカウントロックアウトを強制する。 | F76: 4.04c | G76: 既存証跡・境界確認 | H76: VDI・RDP・リモート環境・RMM・公開サービスの既存証跡を受領する。端末側のリモートアクセス系ツール（拡張・Android・Chrome Remote Desktop）の制御は3.03／3.04で確認する。 | I76: 未確定 | P76: =IFERROR(INDEX(WBS!$O$6:$O$59,MATCH($F76,WBS!$A$6:$A$59,0)),"") -> VDI・リモートアクセス基盤担当
A77: 74 | B77: 47 | C77: 2.H | D77: RDPの管理 | E77: RDPに多要素認証（MFA）を適用する。 | F77: 4.04c | G77: 既存証跡・境界確認 | H77: VDI・RDP・リモート環境・RMM・公開サービスの既存証跡を受領する。端末側のリモートアクセス系ツール（拡張・Android・Chrome Remote Desktop）の制御は3.03／3.04で確認する。 | I77: 未確定 | P77: =IFERROR(INDEX(WBS!$O$6:$O$59,MATCH($F77,WBS!$A$6:$A$59,0)),"") -> VDI・リモートアクセス基盤担当
A78: 75 | B78: 48 | C78: 2.H | D78: RDPの管理 | E78: RDPログイン試行をログに記録する。 | F78: 4.04c | G78: 既存証跡・境界確認 | H78: VDI・RDP・リモート環境・RMM・公開サービスの既存証跡を受領する。端末側のリモートアクセス系ツール（拡張・Android・Chrome Remote Desktop）の制御は3.03／3.04で確認する。 | I78: 未確定 | P78: =IFERROR(INDEX(WBS!$O$6:$O$59,MATCH($F78,WBS!$A$6:$A$59,0)),"") -> VDI・リモートアクセス基盤担当
A79: 76 | B79: 54 | C79: 2.H | D79: SMB管理 | E79: Server Message Block（SMB）プロトコルバージョン1を無効にする。 | F79: 4.04b | G79: 既存証跡・境界確認 | H79: 接続先のSMB・NTLM・暗号化設定は既存証跡を受領する。ChromeOS側のSMBクライアント制御（共有マウント可否・NTLM・NetBIOS探索）は4.09で確認する。 | I79: 未確定 | P79: =IFERROR(INDEX(WBS!$O$6:$O$59,MATCH($F79,WBS!$A$6:$A$59,0)),"") -> ファイルサーバー・ストレージ管理者
A80: 77 | B80: 55 | C80: 2.H | D80: SMB管理 | E80: 既存の依存関係（既存のシステムやアプリケーション）を緩和した後、SM Bをバージョン3（SMBv3）にアップグレードする。 | F80: 4.04b | G80: 既存証跡・境界確認 | H80: 接続先のSMB・NTLM・暗号化設定は既存証跡を受領する。ChromeOS側のSMBクライアント制御（共有マウント可否・NTLM・NetBIOS探索）は4.09で確認する。 | I80: 未確定 | P80: =IFERROR(INDEX(WBS!$O$6:$O$59,MATCH($F80,WBS!$A$6:$A$59,0)),"") -> ファイルサーバー・ストレージ管理者
A81: 78 | B81: 56 | C81: 2.H | D81: SMB管理 | E81: 悪意のある攻撃者がSMBを使用して組織全体にマルウェアを拡散させるた め、以下のガイダンスを実装してSMBv3を強化する。 | F81: 4.04b | G81: 既存証跡・境界確認 | H81: 接続先のSMB・NTLM・暗号化設定は既存証跡を受領する。ChromeOS側のSMBクライアント制御（共有マウント可否・NTLM・NetBIOS探索）は4.09で確認する。 | I81: 未確定 | P81: =IFERROR(INDEX(WBS!$O$6:$O$59,MATCH($F81,WBS!$A$6:$A$59,0)),"") -> ファイルサーバー・ストレージ管理者
A82: 79 | B82: 57 | C82: 2.H | D82: SMB管理 | E82: SMBv3.1.1の使用を義務付ける。（このバージョンには、事前認証の整合 性、拡張AES暗号化、署名暗号化など、セキュリティ保護が強化されてい る） | F82: 4.04b | G82: 既存証跡・境界確認 | H82: 接続先のSMB・NTLM・暗号化設定は既存証跡を受領する。ChromeOS側のSMBクライアント制御（共有マウント可否・NTLM・NetBIOS探索）は4.09で確認する。 | I82: 未確定 | P82: =IFERROR(INDEX(WBS!$O$6:$O$59,MATCH($F82,WBS!$A$6:$A$59,0)),"") -> ファイルサーバー・ストレージ管理者
A83: 80 | B83: 58 | C83: 2.H | D83: SMB管理 | E83: 不要なSMB通信をブロックする。 | F83: 4.04b | G83: 既存証跡・境界確認 | H83: 接続先のSMB・NTLM・暗号化設定は既存証跡を受領する。ChromeOS側のSMBクライアント制御（共有マウント可否・NTLM・NetBIOS探索）は4.09で確認する。 本項目はChromebook側のSMB／NTLM／NetBIOS試験（4.09）も根拠にする。 | I83: 未確定 | M83: 4.09 | P83: =IFERROR(INDEX(WBS!$O$6:$O$59,MATCH($F83,WBS!$A$6:$A$59,0)),"") -> ファイルサーバー・ストレージ管理者
A84: 81 | B84: 59 | C84: 2.H | D84: SMB管理 | E84: 組織ネットワークとの間のSMBの外部アクセスを、インターネットのペリ メータファイアウォールでインバウンドとアウトバウンドのTCPポート445 をブロックすることでブロックする。 | F84: 4.04b | G84: 既存証跡・境界確認 | H84: 接続先のSMB・NTLM・暗号化設定は既存証跡を受領する。ChromeOS側のSMBクライアント制御（共有マウント可否・NTLM・NetBIOS探索）は4.09で確認する。 | I84: 未確定 | P84: =IFERROR(INDEX(WBS!$O$6:$O$59,MATCH($F84,WBS!$A$6:$A$59,0)),"") -> ファイルサーバー・ストレージ管理者
...

Sheet O～X転記用
A2: O～X転記用（評価結果記入シート：グループ各社による一次評価記入欄の下書き）
A3: 入力：D4（会社名コード）と黄色のI～L列。F・G・M～O・R～T列は評価項目対応から自動表示（白）。H列は原票Qの式のプレビューで貼付不可（灰）。貼付手順：①F:G列を原票O:Pへ、②I:O列を原票R:Xへ（いずれも値貼り付け。Q列は原票の式を維持）。貼り付けると既存のR～Uは上書きされるため原票を複製してから行う。並べ替えはしない（原票と同じ行順が前提）。
A4: 会社名コード（必須）→ | E4: 原票O3は「AIS」、Sheet3等の記述は「ADS」。リスト定義の会社名コードから自社を確認して選択する。 | P4: 進捗 | Q4: =COUNTIF(Q7:Q237,"OK")&" / "&COUNTA(A7:A237)&" 行がOK" -> 0 / 231 行がOK
A5: 原票行 | B5: 枝番号 | C5: 主対応WBS | D5: 原票チェック観点 | E5: 原票チェック内容 | F5: 会社名 (原票O列) | G5: 評価要否 (原票P列) | H5: 実装運用状況 (原票Q列・貼付不可) | I5: 成熟度レベル (原票R列) | J5: 成熟度スコア (原票S列) | K5: 証跡名 (原票T列) | L5: 追加情報 (原票U列) | M5: 担当部署 (原票V列) | N5: 回答責任者 (原票W列) | O5: 回答者 (原票X列) | P5: 未記入数 | Q5: チェック | R5: 関連WBS（副） | S5: 確認方針（参考） | T5: 試験ID・判断理由（参考） | U5: 参照行（内部用） | V5: R基準点（内部用） | X5: 成熟度レベル（原票リスト定義） | Y5: スコア
A6: 記入例 | B6: — | C6: — | D6: （貼付対象外） | E6: 例：管理コンソールの許可リストで個人Gmailのログインを拒否する。 | F6: ADS | G6: 対象 | H6: No | I6: 整備ができている | J6: 3 | K6: 試験記録2.01（設定画面・拒否ログ） | L6: 許可リストを設定し、個人Gmailのログイン拒否を実機で確認。Linux環境は未検証のため制約として記載。 | M6: 端末管理者 | N6: （回答責任者名） | O6: （回答者名） | X6: 最適化できている | Y6: 5
A7: 3 | B7: =INDEX(評価項目対応!$B$6:$B$236,$U7) -> 119 | C7: =INDEX(評価項目対応!$F$6:$F$236,$U7) -> 3.08 | D7: =INDEX(評価項目対応!$D$6:$D$236,$U7) -> 資産管理と構成管理 | E7: =INDEX(評価項目対応!$E$6:$E$236,$U7) -> 組織が包括的な資産管理アプローチを持っていることを確認する。 | F7: =IF($D$4="","",$D$4) | G7: =IFERROR(IF(INDEX(評価項目対応!$I$6:$I$236,$U7)="対象","対象",IF(INDEX(評価項目対応!$I$6:$I$236,$U7)="対象外（承認済）","対象外",IF(INDEX(評価項目対応!$I$6:$I$236,$U7)="未確定","n/a",""))),"") -> n/a | H7: =IF(ISBLANK(J7),"",IF(J7=5,"Yes",IF(J7=4,"Yes","No"))) | M7: =IF(INDEX(評価項目対応!$J$6:$J$236,$U7)="","",INDEX(評価項目対応!$J$6:$J$236,$U7)) | N7: =IF(INDEX(評価項目対応!$N$6:$N$236,$U7)="","",INDEX(評価項目対応!$N$6:$N$236,$U7)) | O7: =IF(INDEX(評価項目対応!$O$6:$O$236,$U7)="","",INDEX(評価項目対応!$O$6:$O$236,$U7)) | P7: =COUNTIF(F7:G7,"")+COUNTIF(I7:O7,"")-IF(AND(G7="対象外",K7=""),1,0) -> 8 | Q7: =IF(F7="","会社名コード未設定（D4）",IF(OR(G7="",G7="n/a"),"適用性を確定（評価項目対応I列）",IF(AND(G7="対象外",OR(I7<>"対象外",J7<>"n/a")),"対象外ならR=対象外・S=n/a",IF(AND(G7="対象",OR(I7="対象外",J7="n/a")),"対象なのにR／Sが対象外・n/a",IF(AND(G7="対象",OR(I7="",J7="")),"R・Sを入力",IF(AND(ISNUMBER(J7),ISNUMBER(V7),ABS(N(J7)-N(V7))>=1),"RとSの乖離（案分ならUに明記）",IF(AND(G7="対象",L7=""),"Uに制約・代替策・未検証を記載",IF(AND(G7="対象外",L7=""),"対象外の理由・承認者をUに記載",IF(OR(M7="",N7="",O7=""),"V～Xを入力",IF(P7>0,"未記入あり（P列）","OK")))))))))) -> 会社名コード未設定（D4） | R7: =IF(INDEX(評価項目対応!$M$6:$M$236,$U7)="","",INDEX(評価項目対応!$M$6:$M$236,$U7)) | S7: =INDEX(評価項目対応!$H$6:$H$236,$U7) -> 端末登録に加え、アプリ・データ・重要業務・依存関係・台帳保護を確認する。 | T7: =TRIM(IF(INDEX(評価項目対応!$K$6:$K$236,$U7)="","","試験ID: "&INDEX(評価項目対応!$K$6:$K$236,$U7)&" ")&IF(INDEX(評価項目対応!$L$6:$L$236,$U7)="","","判断理由: "&INDEX(評価項目対応!$L$6:$L$236,$U7))) | U7: =MATCH($A7,評価項目対応!$A$6:$A$236,0) -> 1 | V7: =IFERROR(VLOOKUP(I7,$X$6:$Y$11,2,FALSE()),"") | X7: 態勢が完備している | Y7: 4
A8: 4 | B8: =INDEX(評価項目対応!$B$6:$B$236,$U8) -> 120 | C8: =INDEX(評価項目対応!$F$6:$F$236,$U8) -> 3.08 | D8: =INDEX(評価項目対応!$D$6:$D$236,$U8) -> 資産管理と構成管理 | E8: =INDEX(評価項目対応!$E$6:$E$236,$U8) -> 組織のITアセット、論理的（データ、ソフトウェアなど）および物理的（ ハードウェアなど）の在庫を把握する。 | F8: =IF($D$4="","",$D$4) | G8: =IFERROR(IF(INDEX(評価項目対応!$I$6:$I$236,$U8)="対象","対象",IF(INDEX(評価項目対応!$I$6:$I$236,$U8)="対象外（承認済）","対象外",IF(INDEX(評価項目対応!$I$6:$I$236,$U8)="未確定","n/a",""))),"") -> n/a | H8: =IF(ISBLANK(J8),"",IF(J8=5,"Yes",IF(J8=4,"Yes","No"))) | M8: =IF(INDEX(評価項目対応!$J$6:$J$236,$U8)="","",INDEX(評価項目対応!$J$6:$J$236,$U8)) | N8: =IF(INDEX(評価項目対応!$N$6:$N$236,$U8)="","",INDEX(評価項目対応!$N$6:$N$236,$U8)) | O8: =IF(INDEX(評価項目対応!$O$6:$O$236,$U8)="","",INDEX(評価項目対応!$O$6:$O$236,$U8)) | P8: =COUNTIF(F8:G8,"")+COUNTIF(I8:O8,"")-IF(AND(G8="対象外",K8=""),1,0) -> 8 | Q8: =IF(F8="","会社名コード未設定（D4）",IF(OR(G8="",G8="n/a"),"適用性を確定（評価項目対応I列）",IF(AND(G8="対象外",OR(I8<>"対象外",J8<>"n/a")),"対象外ならR=対象外・S=n/a",IF(AND(G8="対象",OR(I8="対象外",J8="n/a")),"対象なのにR／Sが対象外・n/a",IF(AND(G8="対象",OR(I8="",J8="")),"R・Sを入力",IF(AND(ISNUMBER(J8),ISNUMBER(V8),ABS(N(J8)-N(V8))>=1),"RとSの乖離（案分ならUに明記）",IF(AND(G8="対象",L8=""),"Uに制約・代替策・未検証を記載",IF(AND(G8="対象外",L8=""),"対象外の理由・承認者をUに記載",IF(OR(M8="",N8="",O8=""),"V～Xを入力",IF(P8>0,"未記入あり（P列）","OK")))))))))) -> 会社名コード未設定（D4） | R8: =IF(INDEX(評価項目対応!$M$6:$M$236,$U8)="","",INDEX(評価項目対応!$M$6:$M$236,$U8)) | S8: =INDEX(評価項目対応!$H$6:$H$236,$U8) -> 端末登録に加え、アプリ・データ・重要業務・依存関係・台帳保護を確認する。 | T8: =TRIM(IF(INDEX(評価項目対応!$K$6:$K$236,$U8)="","","試験ID: "&INDEX(評価項目対応!$K$6:$K$236,$U8)&" ")&IF(INDEX(評価項目対応!$L$6:$L$236,$U8)="","","判断理由: "&INDEX(評価項目対応!$L$6:$L$236,$U8))) | U8: =MATCH($A8,評価項目対応!$A$6:$A$236,0) -> 2 | V8: =IFERROR(VLOOKUP(I8,$X$6:$Y$11,2,FALSE()),"") | X8: 整備ができている | Y8: 3
A9: 5 | B9: =INDEX(評価項目対応!$B$6:$B$236,$U9) -> 121 | C9: =INDEX(評価項目対応!$F$6:$F$236,$U9) -> 3.08 | D9: =INDEX(評価項目対応!$D$6:$D$236,$U9) -> 資産管理と構成管理 | E9: =INDEX(評価項目対応!$E$6:$E$236,$U9) -> 健康と安全、収益創出、またはその他の重要なサービスにとって最も重要 なデータまたはシステムを把握し、関連する相互依存関係を理解する。 | F9: =IF($D$4="","",$D$4) | G9: =IFERROR(IF(INDEX(評価項目対応!$I$6:$I$236,$U9)="対象","対象",IF(INDEX(評価項目対応!$I$6:$I$236,$U9)="対象外（承認済）","対象外",IF(INDEX(評価項目対応!$I$6:$I$236,$U9)="未確定","n/a",""))),"") -> n/a | H9: =IF(ISBLANK(J9),"",IF(J9=5,"Yes",IF(J9=4,"Yes","No"))) | M9: =IF(INDEX(評価項目対応!$J$6:$J$236,$U9)="","",INDEX(評価項目対応!$J$6:$J$236,$U9)) | N9: =IF(INDEX(評価項目対応!$N$6:$N$236,$U9)="","",INDEX(評価項目対応!$N$6:$N$236,$U9)) | O9: =IF(INDEX(評価項目対応!$O$6:$O$236,$U9)="","",INDEX(評価項目対応!$O$6:$O$236,$U9)) | P9: =COUNTIF(F9:G9,"")+COUNTIF(I9:O9,"")-IF(AND(G9="対象外",K9=""),1,0) -> 8 | Q9: =IF(F9="","会社名コード未設定（D4）",IF(OR(G9="",G9="n/a"),"適用性を確定（評価項目対応I列）",IF(AND(G9="対象外",OR(I9<>"対象外",J9<>"n/a")),"対象外ならR=対象外・S=n/a",IF(AND(G9="対象",OR(I9="対象外",J9="n/a")),"対象なのにR／Sが対象外・n/a",IF(AND(G9="対象",OR(I9="",J9="")),"R・Sを入力",IF(AND(ISNUMBER(J9),ISNUMBER(V9),ABS(N(J9)-N(V9))>=1),"RとSの乖離（案分ならUに明記）",IF(AND(G9="対象",L9=""),"Uに制約・代替策・未検証を記載",IF(AND(G9="対象外",L9=""),"対象外の理由・承認者をUに記載",IF(OR(M9="",N9="",O9=""),"V～Xを入力",IF(P9>0,"未記入あり（P列）","OK")))))))))) -> 会社名コード未設定（D4） | R9: =IF(INDEX(評価項目対応!$M$6:$M$236,$U9)="","",INDEX(評価項目対応!$M$6:$M$236,$U9)) | S9: =INDEX(評価項目対応!$H$6:$H$236,$U9) -> 重要業務・データ・接続先の依存関係と復旧優先順位を整理する。企業登録のみでは本項目を満たさない。 | T9: =TRIM(IF(INDEX(評価項目対応!$K$6:$K$236,$U9)="","","試験ID: "&INDEX(評価項目対応!$K$6:$K$236,$U9)&" ")&IF(INDEX(評価項目対応!$L$6:$L$236,$U9)="","","判断理由: "&INDEX(評価項目対応!$L$6:$L$236,$U9))) | U9: =MATCH($A9,評価項目対応!$A$6:$A$236,0) -> 3 | V9: =IFERROR(VLOOKUP(I9,$X$6:$Y$11,2,FALSE()),"") | X9: 初期対応ができている | Y9: 2
A10: 6 | B10: =INDEX(評価項目対応!$B$6:$B$236,$U10) -> 122 | C10: =INDEX(評価項目対応!$F$6:$F$236,$U10) -> 3.08 | D10: =INDEX(評価項目対応!$D$6:$D$236,$U10) -> 資産管理と構成管理 | E10: =INDEX(評価項目対応!$E$6:$E$236,$U10) -> セキュリティ制御または保護措置をクリティカルアセットに適用する。 | F10: =IF($D$4="","",$D$4) | G10: =IFERROR(IF(INDEX(評価項目対応!$I$6:$I$236,$U10)="対象","対象",IF(INDEX(評価項目対応!$I$6:$I$236,$U10)="対象外（承認済）","対象外",IF(INDEX(評価項目対応!$I$6:$I$236,$U10)="未確定","n/a",""))),"") -> n/a | H10: =IF(ISBLANK(J10),"",IF(J10=5,"Yes",IF(J10=4,"Yes","No"))) | M10: =IF(INDEX(評価項目対応!$J$6:$J$236,$U10)="","",INDEX(評価項目対応!$J$6:$J$236,$U10)) | N10: =IF(INDEX(評価項目対応!$N$6:$N$236,$U10)="","",INDEX(評価項目対応!$N$6:$N$236,$U10)) | O10: =IF(INDEX(評価項目対応!$O$6:$O$236,$U10)="","",INDEX(評価項目対応!$O$6:$O$236,$U10)) | P10: =COUNTIF(F10:G10,"")+COUNTIF(I10:O10,"")-IF(AND(G10="対象外",K10=""),1,0) -> 8 | Q10: =IF(F10="","会社名コード未設定（D4）",IF(OR(G10="",G10="n/a"),"適用性を確定（評価項目対応I列）",IF(AND(G10="対象外",OR(I10<>"対象外",J10<>"n/a")),"対象外ならR=対象外・S=n/a",IF(AND(G10="対象",OR(I10="対象外",J10="n/a")),"対象なのにR／Sが対象外・n/a",IF(AND(G10="対象",OR(I10="",J10="")),"R・Sを入力",IF(AND(ISNUMBER(J10),ISNUMBER(V10),ABS(N(J10)-N(V10))>=1),"RとSの乖離（案分ならUに明記）",IF(AND(G10="対象",L10=""),"Uに制約・代替策・未検証を記載",IF(AND(G10="対象外",L10=""),"対象外の理由・承認者をUに記載",IF(OR(M10="",N10="",O10=""),"V～Xを入力",IF(P10>0,"未記入あり（P列）","OK")))))))))) -> 会社名コード未設定（D4） | R10: =IF(INDEX(評価項目対応!$M$6:$M$236,$U10)="","",INDEX(評価項目対応!$M$6:$M$236,$U10)) | S10: =INDEX(評価項目対応!$H$6:$H$236,$U10) -> 端末登録に加え、アプリ・データ・重要業務・依存関係・台帳保護を確認する。 | T10: =TRIM(IF(INDEX(評価項目対応!$K$6:$K$236,$U10)="","","試験ID: "&INDEX(評価項目対応!$K$6:$K$236,$U10)&" ")&IF(INDEX(評価項目対応!$L$6:$L$236,$U10)="","","判断理由: "&INDEX(評価項目対応!$L$6:$L$236,$U10))) | U10: =MATCH($A10,評価項目対応!$A$6:$A$236,0) -> 4 | V10: =IFERROR(VLOOKUP(I10,$X$6:$Y$11,2,FALSE()),"") | X10: 未対応 | Y10: 1
A11: 7 | B11: =INDEX(評価項目対応!$B$6:$B$236,$U11) -> 153 | C11: =INDEX(評価項目対応!$F$6:$F$236,$U11) -> 4.04a | D11: =INDEX(評価項目対応!$D$6:$D$236,$U11) -> データセンター管理 | E11: =INDEX(評価項目対応!$E$6:$E$236,$U11) -> データセンターが定期的にパッチが適用されていることを確認する。重大 な脆弱性のパッチは、できるだけ早く適用する。 | F11: =IF($D$4="","",$D$4) | G11: =IFERROR(IF(INDEX(評価項目対応!$I$6:$I$236,$U11)="対象","対象",IF(INDEX(評価項目対応!$I$6:$I$236,$U11)="対象外（承認済）","対象外",IF(INDEX(評価項目対応!$I$6:$I$236,$U11)="未確定","n/a",""))),"") -> n/a | H11: =IF(ISBLANK(J11),"",IF(J11=5,"Yes",IF(J11=4,"Yes","No"))) | M11: =IF(INDEX(評価項目対応!$J$6:$J$236,$U11)="","",INDEX(評価項目対応!$J$6:$J$236,$U11)) | N11: =IF(INDEX(評価項目対応!$N$6:$N$236,$U11)="","",INDEX(評価項目対応!$N$6:$N$236,$U11)) | O11: =IF(INDEX(評価項目対応!$O$6:$O$236,$U11)="","",INDEX(評価項目対応!$O$6:$O$236,$U11)) | P11: =COUNTIF(F11:G11,"")+COUNTIF(I11:O11,"")-IF(AND(G11="対象外",K11=""),1,0) -> 8 | Q11: =IF(F11="","会社名コード未設定（D4）",IF(OR(G11="",G11="n/a"),"適用性を確定（評価項目対応I列）",IF(AND(G11="対象外",OR(I11<>"対象外",J11<>"n/a")),"対象外ならR=対象外・S=n/a",IF(AND(G11="対象",OR(I11="対象外",J11="n/a")),"対象なのにR／Sが対象外・n/a",IF(AND(G11="対象",OR(I11="",J11="")),"R・Sを入力",IF(AND(ISNUMBER(J11),ISNUMBER(V11),ABS(N(J11)-N(V11))>=1),"RとSの乖離（案分ならUに明記）",IF(AND(G11="対象",L11=""),"Uに制約・代替策・未検証を記載",IF(AND(G11="対象外",L11=""),"対象外の理由・承認者をUに記載",IF(OR(M11="",N11="",O11=""),"V～Xを入力",IF(P11>0,"未記入あり（P列）","OK")))))))))) -> 会社名コード未設定（D4） | R11: =IF(INDEX(評価項目対応!$M$6:$M$236,$U11)="","",INDEX(評価項目対応!$M$6:$M$236,$U11)) | S11: =INDEX(評価項目対応!$H$6:$H$236,$U11) -> 原票の「データセンター」表記は原文のDC（Domain Controller）の訳。ADドメインコントローラーの設定・パッチ・監視の既存証跡を担当者から受領する。ChromeOS利用だけで対象外にしない。 | T11: =TRIM(IF(INDEX(評価項目対応!$K$6:$K$236,$U11)="","","試験ID: "&INDEX(評価項目対応!$K$6:$K$236,$U11)&" ")&IF(INDEX(評価項目対応!$L$6:$L$236,$U11)="","","判断理由: "&INDEX(評価項目対応!$L$6:$L$236,$U11))) | U11: =MATCH($A11,評価項目対応!$A$6:$A$236,0) -> 5 | V11: =IFERROR(VLOOKUP(I11,$X$6:$Y$11,2,FALSE()),"") | X11: 対象外 | Y11: n/a
A12: 8 | B12: =INDEX(評価項目対応!$B$6:$B$236,$U12) -> 36 | C12: =INDEX(評価項目対応!$F$6:$F$236,$U12) -> 1.02 | D12: =INDEX(評価項目対応!$D$6:$D$236,$U12) -> IaCの利用と管理 | E12: =INDEX(評価項目対応!$E$6:$E$236,$U12) -> IaCテンプレートを展開する前に、静的セキュリティスキャンツールでテ ストする。 | F12: =IF($D$4="","",$D$4) | G12: =IFERROR(IF(INDEX(評価項目対応!$I$6:$I$236,$U12)="対象","対象",IF(INDEX(評価項目対応!$I$6:$I$236,$U12)="対象外（承認済）","対象外",IF(INDEX(評価項目対応!$I$6:$I$236,$U12)="未確定","n/a",""))),"") -> n/a | H12: =IF(ISBLANK(J12),"",IF(J12=5,"Yes",IF(J12=4,"Yes","No"))) | M12: =IF(INDEX(評価項目対応!$J$6:$J$236,$U12)="","",INDEX(評価項目対応!$J$6:$J$236,$U12)) | N12: =IF(INDEX(評価項目対応!$N$6:$N$236,$U12)="","",INDEX(評価項目対応!$N$6:$N$236,$U12)) | O12: =IF(INDEX(評価項目対応!$O$6:$O$236,$U12)="","",INDEX(評価項目対応!$O$6:$O$236,$U12)) | P12: =COUNTIF(F12:G12,"")+COUNTIF(I12:O12,"")-IF(AND(G12="対象外",K12=""),1,0) -> 8 | Q12: =IF(F12="","会社名コード未設定（D4）",IF(OR(G12="",G12="n/a"),"適用性を確定（評価項目対応I列）",IF(AND(G12="対象外",OR(I12<>"対象外",J12<>"n/a")),"対象外ならR=対象外・S=n/a",IF(AND(G12="対象",OR(I12="対象外",J12="n/a")),"対象なのにR／Sが対象外・n/a",IF(AND(G12="対象",OR(I12="",J12="")),"R・Sを入力",IF(AND(ISNUMBER(J12),ISNUMBER(V12),ABS(N(J12)-N(V12))>=1),"RとSの乖離（案分ならUに明記）",IF(AND(G12="対象",L12=""),"Uに制約・代替策・未検証を記載",IF(AND(G12="対象外",L12=""),"対象外の理由・承認者をUに記載",IF(OR(M12="",N12="",O12=""),"V～Xを入力",IF(P12>0,"未記入あり（P列）","OK")))))))))) -> 会社名コード未設定（D4） | R12: =IF(INDEX(評価項目対応!$M$6:$M$236,$U12)="","",INDEX(評価項目対応!$M$6:$M$236,$U12)) | S12: =INDEX(評価項目対応!$H$6:$H$236,$U12) -> IaC利用の有無を関連クラウドも含めて確認する。未使用なら範囲と理由を記載する。 | T12: =TRIM(IF(INDEX(評価項目対応!$K$6:$K$236,$U12)="","","試験ID: "&INDEX(評価項目対応!$K$6:$K$236,$U12)&" ")&IF(INDEX(評価項目対応!$L$6:$L$236,$U12)="","","判断理由: "&INDEX(評価項目対応!$L$6:$L$236,$U12))) | U12: =MATCH($A12,評価項目対応!$A$6:$A$236,0) -> 6 | V12: =IFERROR(VLOOKUP(I12,$X$6:$Y$11,2,FALSE()),"")
A13: 9 | B13: =INDEX(評価項目対応!$B$6:$B$236,$U13) -> 37 | C13: =INDEX(評価項目対応!$F$6:$F$236,$U13) -> 1.02 | D13: =INDEX(評価項目対応!$D$6:$D$236,$U13) -> IaCの利用と管理 | E13: =INDEX(評価項目対応!$E$6:$E$236,$U13) -> 静的セキュリティスキャンツールで設定ミスとセキュリティギャップを特 定する。 | F13: =IF($D$4="","",$D$4) | G13: =IFERROR(IF(INDEX(評価項目対応!$I$6:$I$236,$U13)="対象","対象",IF(INDEX(評価項目対応!$I$6:$I$236,$U13)="対象外（承認済）","対象外",IF(INDEX(評価項目対応!$I$6:$I$236,$U13)="未確定","n/a",""))),"") -> n/a | H13: =IF(ISBLANK(J13),"",IF(J13=5,"Yes",IF(J13=4,"Yes","No"))) | M13: =IF(INDEX(評価項目対応!$J$6:$J$236,$U13)="","",INDEX(評価項目対応!$J$6:$J$236,$U13)) | N13: =IF(INDEX(評価項目対応!$N$6:$N$236,$U13)="","",INDEX(評価項目対応!$N$6:$N$236,$U13)) | O13: =IF(INDEX(評価項目対応!$O$6:$O$236,$U13)="","",INDEX(評価項目対応!$O$6:$O$236,$U13)) | P13: =COUNTIF(F13:G13,"")+COUNTIF(I13:O13,"")-IF(AND(G13="対象外",K13=""),1,0) -> 8 | Q13: =IF(F13="","会社名コード未設定（D4）",IF(OR(G13="",G13="n/a"),"適用性を確定（評価項目対応I列）",IF(AND(G13="対象外",OR(I13<>"対象外",J13<>"n/a")),"対象外ならR=対象外・S=n/a",IF(AND(G13="対象",OR(I13="対象外",J13="n/a")),"対象なのにR／Sが対象外・n/a",IF(AND(G13="対象",OR(I13="",J13="")),"R・Sを入力",IF(AND(ISNUMBER(J13),ISNUMBER(V13),ABS(N(J13)-N(V13))>=1),"RとSの乖離（案分ならUに明記）",IF(AND(G13="対象",L13=""),"Uに制約・代替策・未検証を記載",IF(AND(G13="対象外",L13=""),"対象外の理由・承認者をUに記載",IF(OR(M13="",N13="",O13=""),"V～Xを入力",IF(P13>0,"未記入あり（P列）","OK")))))))))) -> 会社名コード未設定（D4） | R13: =IF(INDEX(評価項目対応!$M$6:$M$236,$U13)="","",INDEX(評価項目対応!$M$6:$M$236,$U13)) | S13: =INDEX(評価項目対応!$H$6:$H$236,$U13) -> IaC利用の有無を関連クラウドも含めて確認する。未使用なら範囲と理由を記載する。 | T13: =TRIM(IF(INDEX(評価項目対応!$K$6:$K$236,$U13)="","","試験ID: "&INDEX(評価項目対応!$K$6:$K$236,$U13)&" ")&IF(INDEX(評価項目対応!$L$6:$L$236,$U13)="","","判断理由: "&INDEX(評価項目対応!$L$6:$L$236,$U13))) | U13: =MATCH($A13,評価項目対応!$A$6:$A$236,0) -> 7 | V13: =IFERROR(VLOOKUP(I13,$X$6:$Y$11,2,FALSE()),"")
A14: 10 | B14: =INDEX(評価項目対応!$B$6:$B$236,$U14) -> 4 | C14: =INDEX(評価項目対応!$F$6:$F$236,$U14) -> 1.02 | D14: =INDEX(評価項目対応!$D$6:$D$236,$U14) -> IaCの利用と管理 | E14: =INDEX(評価項目対応!$E$6:$E$236,$U14) -> インフラストラクチャをコード（IaC）を使用してクラウドリソースを展 開および更新する。 | F14: =IF($D$4="","",$D$4) | G14: =IFERROR(IF(INDEX(評価項目対応!$I$6:$I$236,$U14)="対象","対象",IF(INDEX(評価項目対応!$I$6:$I$236,$U14)="対象外（承認済）","対象外",IF(INDEX(評価項目対応!$I$6:$I$236,$U14)="未確定","n/a",""))),"") -> n/a | H14: =IF(ISBLANK(J14),"",IF(J14=5,"Yes",IF(J14=4,"Yes","No"))) | M14: =IF(INDEX(評価項目対応!$J$6:$J$236,$U14)="","",INDEX(評価項目対応!$J$6:$J$236,$U14)) | N14: =IF(INDEX(評価項目対応!$N$6:$N$236,$U14)="","",INDEX(評価項目対応!$N$6:$N$236,$U14)) | O14: =IF(INDEX(評価項目対応!$O$6:$O$236,$U14)="","",INDEX(評価項目対応!$O$6:$O$236,$U14)) | P14: =COUNTIF(F14:G14,"")+COUNTIF(I14:O14,"")-IF(AND(G14="対象外",K14=""),1,0) -> 8 | Q14: =IF(F14="","会社名コード未設定（D4）",IF(OR(G14="",G14="n/a"),"適用性を確定（評価項目対応I列）",IF(AND(G14="対象外",OR(I14<>"対象外",J14<>"n/a")),"対象外ならR=対象外・S=n/a",IF(AND(G14="対象",OR(I14="対象外",J14="n/a")),"対象なのにR／Sが対象外・n/a",IF(AND(G14="対象",OR(I14="",J14="")),"R・Sを入力",IF(AND(ISNUMBER(J14),ISNUMBER(V14),ABS(N(J14)-N(V14))>=1),"RとSの乖離（案分ならUに明記）",IF(AND(G14="対象",L14=""),"Uに制約・代替策・未検証を記載",IF(AND(G14="対象外",L14=""),"対象外の理由・承認者をUに記載",IF(OR(M14="",N14="",O14=""),"V～Xを入力",IF(P14>0,"未記入あり（P列）","OK")))))))))) -> 会社名コード未設定（D4） | R14: =IF(INDEX(評価項目対応!$M$6:$M$236,$U14)="","",INDEX(評価項目対応!$M$6:$M$236,$U14)) | S14: =INDEX(評価項目対応!$H$6:$H$236,$U14) -> IaC利用の有無を関連クラウドも含めて確認する。未使用なら範囲と理由を記載する。 | T14: =TRIM(IF(INDEX(評価項目対応!$K$6:$K$236,$U14)="","","試験ID: "&INDEX(評価項目対応!$K$6:$K$236,$U14)&" ")&IF(INDEX(評価項目対応!$L$6:$L$236,$U14)="","","判断理由: "&INDEX(評価項目対応!$L$6:$L$236,$U14))) | U14: =MATCH($A14,評価項目対応!$A$6:$A$236,0) -> 8 | V14: =IFERROR(VLOOKUP(I14,$X$6:$Y$11,2,FALSE()),"")
A15: 11 | B15: =INDEX(評価項目対応!$B$6:$B$236,$U15) -> 5 | C15: =INDEX(評価項目対応!$F$6:$F$236,$U15) -> 1.02 | D15: =INDEX(評価項目対応!$D$6:$D$236,$U15) -> IaCの利用と管理 | E15: =INDEX(評価項目対応!$E$6:$E$236,$U15) -> IaCのテンプレートファイルのバックアップをオフラインで保管する。 | F15: =IF($D$4="","",$D$4) | G15: =IFERROR(IF(INDEX(評価項目対応!$I$6:$I$236,$U15)="対象","対象",IF(INDEX(評価項目対応!$I$6:$I$236,$U15)="対象外（承認済）","対象外",IF(INDEX(評価項目対応!$I$6:$I$236,$U15)="未確定","n/a",""))),"") -> n/a | H15: =IF(ISBLANK(J15),"",IF(J15=5,"Yes",IF(J15=4,"Yes","No"))) | M15: =IF(INDEX(評価項目対応!$J$6:$J$236,$U15)="","",INDEX(評価項目対応!$J$6:$J$236,$U15)) | N15: =IF(INDEX(評価項目対応!$N$6:$N$236,$U15)="","",INDEX(評価項目対応!$N$6:$N$236,$U15)) | O15: =IF(INDEX(評価項目対応!$O$6:$O$236,$U15)="","",INDEX(評価項目対応!$O$6:$O$236,$U15)) | P15: =COUNTIF(F15:G15,"")+COUNTIF(I15:O15,"")-IF(AND(G15="対象外",K15=""),1,0) -> 8 | Q15: =IF(F15="","会社名コード未設定（D4）",IF(OR(G15="",G15="n/a"),"適用性を確定（評価項目対応I列）",IF(AND(G15="対象外",OR(I15<>"対象外",J15<>"n/a")),"対象外ならR=対象外・S=n/a",IF(AND(G15="対象",OR(I15="対象外",J15="n/a")),"対象なのにR／Sが対象外・n/a",IF(AND(G15="対象",OR(I15="",J15="")),"R・Sを入力",IF(AND(ISNUMBER(J15),ISNUMBER(V15),ABS(N(J15)-N(V15))>=1),"RとSの乖離（案分ならUに明記）",IF(AND(G15="対象",L15=""),"Uに制約・代替策・未検証を記載",IF(AND(G15="対象外",L15=""),"対象外の理由・承認者をUに記載",IF(OR(M15="",N15="",O15=""),"V～Xを入力",IF(P15>0,"未記入あり（P列）","OK")))))))))) -> 会社名コード未設定（D4） | R15: =IF(INDEX(評価項目対応!$M$6:$M$236,$U15)="","",INDEX(評価項目対応!$M$6:$M$236,$U15)) | S15: =INDEX(評価項目対応!$H$6:$H$236,$U15) -> IaC利用の有無を関連クラウドも含めて確認する。未使用なら範囲と理由を記載する。 | T15: =TRIM(IF(INDEX(評価項目対応!$K$6:$K$236,$U15)="","","試験ID: "&INDEX(評価項目対応!$K$6:$K$236,$U15)&" ")&IF(INDEX(評価項目対応!$L$6:$L$236,$U15)="","","判断理由: "&INDEX(評価項目対応!$L$6:$L$236,$U15))) | U15: =MATCH($A15,評価項目対応!$A$6:$A$236,0) -> 9 | V15: =IFERROR(VLOOKUP(I15,$X$6:$Y$11,2,FALSE()),"")
A16: 12 | B16: =INDEX(評価項目対応!$B$6:$B$236,$U16) -> 6 | C16: =INDEX(評価項目対応!$F$6:$F$236,$U16) -> 1.02 | D16: =INDEX(評価項目対応!$D$6:$D$236,$U16) -> IaCの利用と管理 | E16: =INDEX(評価項目対応!$E$6:$E$236,$U16) -> ヒューマンエラーの削減のためのIaCコードはバージョン管理する。 | F16: =IF($D$4="","",$D$4) | G16: =IFERROR(IF(INDEX(評価項目対応!$I$6:$I$236,$U16)="対象","対象",IF(INDEX(評価項目対応!$I$6:$I$236,$U16)="対象外（承認済）","対象外",IF(INDEX(評価項目対応!$I$6:$I$236,$U16)="未確定","n/a",""))),"") -> n/a | H16: =IF(ISBLANK(J16),"",IF(J16=5,"Yes",IF(J16=4,"Yes","No"))) | M16: =IF(INDEX(評価項目対応!$J$6:$J$236,$U16)="","",INDEX(評価項目対応!$J$6:$J$236,$U16)) | N16: =IF(INDEX(評価項目対応!$N$6:$N$236,$U16)="","",INDEX(評価項目対応!$N$6:$N$236,$U16)) | O16: =IF(INDEX(評価項目対応!$O$6:$O$236,$U16)="","",INDEX(評価項目対応!$O$6:$O$236,$U16)) | P16: =COUNTIF(F16:G16,"")+COUNTIF(I16:O16,"")-IF(AND(G16="対象外",K16=""),1,0) -> 8 | Q16: =IF(F16="","会社名コード未設定（D4）",IF(OR(G16="",G16="n/a"),"適用性を確定（評価項目対応I列）",IF(AND(G16="対象外",OR(I16<>"対象外",J16<>"n/a")),"対象外ならR=対象外・S=n/a",IF(AND(G16="対象",OR(I16="対象外",J16="n/a")),"対象なのにR／Sが対象外・n/a",IF(AND(G16="対象",OR(I16="",J16="")),"R・Sを入力",IF(AND(ISNUMBER(J16),ISNUMBER(V16),ABS(N(J16)-N(V16))>=1),"RとSの乖離（案分ならUに明記）",IF(AND(G16="対象",L16=""),"Uに制約・代替策・未検証を記載",IF(AND(G16="対象外",L16=""),"対象外の理由・承認者をUに記載",IF(OR(M16="",N16="",O16=""),"V～Xを入力",IF(P16>0,"未記入あり（P列）","OK")))))))))) -> 会社名コード未設定（D4） | R16: =IF(INDEX(評価項目対応!$M$6:$M$236,$U16)="","",INDEX(評価項目対応!$M$6:$M$236,$U16)) | S16: =INDEX(評価項目対応!$H$6:$H$236,$U16) -> IaC利用の有無を関連クラウドも含めて確認する。未使用なら範囲と理由を記載する。 | T16: =TRIM(IF(INDEX(評価項目対応!$K$6:$K$236,$U16)="","","試験ID: "&INDEX(評価項目対応!$K$6:$K$236,$U16)&" ")&IF(INDEX(評価項目対応!$L$6:$L$236,$U16)="","","判断理由: "&INDEX(評価項目対応!$L$6:$L$236,$U16))) | U16: =MATCH($A16,評価項目対応!$A$6:$A$236,0) -> 10 | V16: =IFERROR(VLOOKUP(I16,$X$6:$Y$11,2,FALSE()),"")
A17: 13 | B17: =INDEX(評価項目対応!$B$6:$B$236,$U17) -> 7 | C17: =INDEX(評価項目対応!$F$6:$F$236,$U17) -> 1.02 | D17: =INDEX(評価項目対応!$D$6:$D$236,$U17) -> IaCの利用と管理 | E17: =INDEX(評価項目対応!$E$6:$E$236,$U17) -> IaCのテンプレートへの変更を監査する。 | F17: =IF($D$4="","",$D$4) | G17: =IFERROR(IF(INDEX(評価項目対応!$I$6:$I$236,$U17)="対象","対象",IF(INDEX(評価項目対応!$I$6:$I$236,$U17)="対象外（承認済）","対象外",IF(INDEX(評価項目対応!$I$6:$I$236,$U17)="未確定","n/a",""))),"") -> n/a | H17: =IF(ISBLANK(J17),"",IF(J17=5,"Yes",IF(J17=4,"Yes","No"))) | M17: =IF(INDEX(評価項目対応!$J$6:$J$236,$U17)="","",INDEX(評価項目対応!$J$6:$J$236,$U17)) | N17: =IF(INDEX(評価項目対応!$N$6:$N$236,$U17)="","",INDEX(評価項目対応!$N$6:$N$236,$U17)) | O17: =IF(INDEX(評価項目対応!$O$6:$O$236,$U17)="","",INDEX(評価項目対応!$O$6:$O$236,$U17)) | P17: =COUNTIF(F17:G17,"")+COUNTIF(I17:O17,"")-IF(AND(G17="対象外",K17=""),1,0) -> 8 | Q17: =IF(F17="","会社名コード未設定（D4）",IF(OR(G17="",G17="n/a"),"適用性を確定（評価項目対応I列）",IF(AND(G17="対象外",OR(I17<>"対象外",J17<>"n/a")),"対象外ならR=対象外・S=n/a",IF(AND(G17="対象",OR(I17="対象外",J17="n/a")),"対象なのにR／Sが対象外・n/a",IF(AND(G17="対象",OR(I17="",J17="")),"R・Sを入力",IF(AND(ISNUMBER(J17),ISNUMBER(V17),ABS(N(J17)-N(V17))>=1),"RとSの乖離（案分ならUに明記）",IF(AND(G17="対象",L17=""),"Uに制約・代替策・未検証を記載",IF(AND(G17="対象外",L17=""),"対象外の理由・承認者をUに記載",IF(OR(M17="",N17="",O17=""),"V～Xを入力",IF(P17>0,"未記入あり（P列）","OK")))))))))) -> 会社名コード未設定（D4） | R17: =IF(INDEX(評価項目対応!$M$6:$M$236,$U17)="","",INDEX(評価項目対応!$M$6:$M$236,$U17)) | S17: =INDEX(評価項目対応!$H$6:$H$236,$U17) -> IaC利用の有無を関連クラウドも含めて確認する。未使用なら範囲と理由を記載する。 | T17: =TRIM(IF(INDEX(評価項目対応!$K$6:$K$236,$U17)="","","試験ID: "&INDEX(評価項目対応!$K$6:$K$236,$U17)&" ")&IF(INDEX(評価項目対応!$L$6:$L$236,$U17)="","","判断理由: "&INDEX(評価項目対応!$L$6:$L$236,$U17))) | U17: =MATCH($A17,評価項目対応!$A$6:$A$236,0) -> 11 | V17: =IFERROR(VLOOKUP(I17,$X$6:$Y$11,2,FALSE()),"")
A18: 14 | B18: =INDEX(評価項目対応!$B$6:$B$236,$U18) -> 39 | C18: =INDEX(評価項目対応!$F$6:$F$236,$U18) -> 3.08 | D18: =INDEX(評価項目対応!$D$6:$D$236,$U18) -> 構成ドリフトのチェッ ク | E18: =INDEX(評価項目対応!$E$6:$E$236,$U18) -> テンプレート展開の外で変更または導入されたリソースを特定するために 、構成ドリフト（期待された状態からの乖離）を定期的にチェックする。 | F18: =IF($D$4="","",$D$4) | G18: =IFERROR(IF(INDEX(評価項目対応!$I$6:$I$236,$U18)="対象","対象",IF(INDEX(評価項目対応!$I$6:$I$236,$U18)="対象外（承認済）","対象外",IF(INDEX(評価項目対応!$I$6:$I$236,$U18)="未確定","n/a",""))),"") -> n/a | H18: =IF(ISBLANK(J18),"",IF(J18=5,"Yes",IF(J18=4,"Yes","No"))) | M18: =IF(INDEX(評価項目対応!$J$6:$J$236,$U18)="","",INDEX(評価項目対応!$J$6:$J$236,$U18)) | N18: =IF(INDEX(評価項目対応!$N$6:$N$236,$U18)="","",INDEX(評価項目対応!$N$6:$N$236,$U18)) | O18: =IF(INDEX(評価項目対応!$O$6:$O$236,$U18)="","",INDEX(評価項目対応!$O$6:$O$236,$U18)) | P18: =COUNTIF(F18:G18,"")+COUNTIF(I18:O18,"")-IF(AND(G18="対象外",K18=""),1,0) -> 8 | Q18: =IF(F18="","会社名コード未設定（D4）",IF(OR(G18="",G18="n/a"),"適用性を確定（評価項目対応I列）",IF(AND(G18="対象外",OR(I18<>"対象外",J18<>"n/a")),"対象外ならR=対象外・S=n/a",IF(AND(G18="対象",OR(I18="対象外",J18="n/a")),"対象なのにR／Sが対象外・n/a",IF(AND(G18="対象",OR(I18="",J18="")),"R・Sを入力",IF(AND(ISNUMBER(J18),ISNUMBER(V18),ABS(N(J18)-N(V18))>=1),"RとSの乖離（案分ならUに明記）",IF(AND(G18="対象",L18=""),"Uに制約・代替策・未検証を記載",IF(AND(G18="対象外",L18=""),"対象外の理由・承認者をUに記載",IF(OR(M18="",N18="",O18=""),"V～Xを入力",IF(P18>0,"未記入あり（P列）","OK")))))))))) -> 会社名コード未設定（D4） | R18: =IF(INDEX(評価項目対応!$M$6:$M$236,$U18)="","",INDEX(評価項目対応!$M$6:$M$236,$U18)) | S18: =INDEX(評価項目対応!$H$6:$H$236,$U18) -> Google管理ポリシーの承認基線と実効値、変更履歴、差分検出・復元を確認する。 | T18: =TRIM(IF(INDEX(評価項目対応!$K$6:$K$236,$U18)="","","試験ID: "&INDEX(評価項目対応!$K$6:$K$236,$U18)&" ")&IF(INDEX(評価項目対応!$L$6:$L$236,$U18)="","","判断理由: "&INDEX(評価項目対応!$L$6:$L$236,$U18))) | U18: =MATCH($A18,評価項目対応!$A$6:$A$236,0) -> 12 | V18: =IFERROR(VLOOKUP(I18,$X$6:$Y$11,2,FALSE()),"")
A19: 15 | B19: =INDEX(評価項目対応!$B$6:$B$236,$U19) -> 40 | C19: =INDEX(評価項目対応!$F$6:$F$236,$U19) -> 3.08 | D19: =INDEX(評価項目対応!$D$6:$D$236,$U19) -> 構成ドリフトのチェッ ク | E19: =INDEX(評価項目対応!$E$6:$E$236,$U19) -> 構成ドリフト（期待された状態からの乖離）チェックにより、新しいセキ ュリティギャップと設定ミスが導入される可能性を減らす。 | F19: =IF($D$4="","",$D$4) | G19: =IFERROR(IF(INDEX(評価項目対応!$I$6:$I$236,$U19)="対象","対象",IF(INDEX(評価項目対応!$I$6:$I$236,$U19)="対象外（承認済）","対象外",IF(INDEX(評価項目対応!$I$6:$I$236,$U19)="未確定","n/a",""))),"") -> n/a | H19: =IF(ISBLANK(J19),"",IF(J19=5,"Yes",IF(J19=4,"Yes","No"))) | M19: =IF(INDEX(評価項目対応!$J$6:$J$236,$U19)="","",INDEX(評価項目対応!$J$6:$J$236,$U19)) | N19: =IF(INDEX(評価項目対応!$N$6:$N$236,$U19)="","",INDEX(評価項目対応!$N$6:$N$236,$U19)) | O19: =IF(INDEX(評価項目対応!$O$6:$O$236,$U19)="","",INDEX(評価項目対応!$O$6:$O$236,$U19)) | P19: =COUNTIF(F19:G19,"")+COUNTIF(I19:O19,"")-IF(AND(G19="対象外",K19=""),1,0) -> 8 | Q19: =IF(F19="","会社名コード未設定（D4）",IF(OR(G19="",G19="n/a"),"適用性を確定（評価項目対応I列）",IF(AND(G19="対象外",OR(I19<>"対象外",J19<>"n/a")),"対象外ならR=対象外・S=n/a",IF(AND(G19="対象",OR(I19="対象外",J19="n/a")),"対象なのにR／Sが対象外・n/a",IF(AND(G19="対象",OR(I19="",J19="")),"R・Sを入力",IF(AND(ISNUMBER(J19),ISNUMBER(V19),ABS(N(J19)-N(V19))>=1),"RとSの乖離（案分ならUに明記）",IF(AND(G19="対象",L19=""),"Uに制約・代替策・未検証を記載",IF(AND(G19="対象外",L19=""),"対象外の理由・承認者をUに記載",IF(OR(M19="",N19="",O19=""),"V～Xを入力",IF(P19>0,"未記入あり（P列）","OK")))))))))) -> 会社名コード未設定（D4） | R19: =IF(INDEX(評価項目対応!$M$6:$M$236,$U19)="","",INDEX(評価項目対応!$M$6:$M$236,$U19)) | S19: =INDEX(評価項目対応!$H$6:$H$236,$U19) -> Google管理ポリシーの承認基線と実効値、変更履歴、差分検出・復元を確認する。 | T19: =TRIM(IF(INDEX(評価項目対応!$K$6:$K$236,$U19)="","","試験ID: "&INDEX(評価項目対応!$K$6:$K$236,$U19)&" ")&IF(INDEX(評価項目対応!$L$6:$L$236,$U19)="","","判断理由: "&INDEX(評価項目対応!$L$6:$L$236,$U19))) | U19: =MATCH($A19,評価項目対応!$A$6:$A$236,0) -> 13 | V19: =IFERROR(VLOOKUP(I19,$X$6:$Y$11,2,FALSE()),"")
A20: 16 | B20: =INDEX(評価項目対応!$B$6:$B$236,$U20) -> 28 | C20: =INDEX(評価項目対応!$F$6:$F$236,$U20) -> 3.07 | D20: =INDEX(評価項目対応!$D$6:$D$236,$U20) -> 脆弱性管理 | E20: =INDEX(評価項目対応!$E$6:$E$236,$U20) -> 攻撃対象領域を制限するため、定期的な脆弱性スキャンを実施する。 | F20: =IF($D$4="","",$D$4) | G20: =IFERROR(IF(INDEX(評価項目対応!$I$6:$I$236,$U20)="対象","対象",IF(INDEX(評価項目対応!$I$6:$I$236,$U20)="対象外（承認済）","対象外",IF(INDEX(評価項目対応!$I$6:$I$236,$U20)="未確定","n/a",""))),"") -> n/a | H20: =IF(ISBLANK(J20),"",IF(J20=5,"Yes",IF(J20=4,"Yes","No"))) | M20: =IF(INDEX(評価項目対応!$J$6:$J$236,$U20)="","",INDEX(評価項目対応!$J$6:$J$236,$U20)) | N20: =IF(INDEX(評価項目対応!$N$6:$N$236,$U20)="","",INDEX(評価項目対応!$N$6:$N$236,$U20)) | O20: =IF(INDEX(評価項目対応!$O$6:$O$236,$U20)="","",INDEX(評価項目対応!$O$6:$O$236,$U20)) | P20: =COUNTIF(F20:G20,"")+COUNTIF(I20:O20,"")-IF(AND(G20="対象外",K20=""),1,0) -> 8 | Q20: =IF(F20="","会社名コード未設定（D4）",IF(OR(G20="",G20="n/a"),"適用性を確定（評価項目対応I列）",IF(AND(G20="対象外",OR(I20<>"対象外",J20<>"n/a")),"対象外ならR=対象外・S=n/a",IF(AND(G20="対象",OR(I20="対象外",J20="n/a")),"対象なのにR／Sが対象外・n/a",IF(AND(G20="対象",OR(I20="",J20="")),"R・Sを入力",IF(AND(ISNUMBER(J20),ISNUMBER(V20),ABS(N(J20)-N(V20))>=1),"RとSの乖離（案分ならUに明記）",IF(AND(G20="対象",L20=""),"Uに制約・代替策・未検証を記載",IF(AND(G20="対象外",L20=""),"対象外の理由・承認者をUに記載",IF(OR(M20="",N20="",O20=""),"V～Xを入力",IF(P20>0,"未記入あり（P列）","OK")))))))))) -> 会社名コード未設定（D4） | R20: =IF(INDEX(評価項目対応!$M$6:$M$236,$U20)="","",INDEX(評価項目対応!$M$6:$M$236,$U20)) | S20: =INDEX(評価項目対応!$H$6:$H$236,$U20) -> ChromeOSと接続先・ネットワーク製品を分けて脆弱性・更新運用を確認する。 | T20: =TRIM(IF(INDEX(評価項目対応!$K$6:$K$236,$U20)="","","試験ID: "&INDEX(評価項目対応!$K$6:$K$236,$U20)&" ")&IF(INDEX(評価項目対応!$L$6:$L$236,$U20)="","","判断理由: "&INDEX(評価項目対応!$L$6:$L$236,$U20))) | U20: =MATCH($A20,評価項目対応!$A$6:$A$236,0) -> 14 | V20: =IFERROR(VLOOKUP(I20,$X$6:$Y$11,2,FALSE()),"")
A21: 17 | B21: =INDEX(評価項目対応!$B$6:$B$236,$U21) -> 29 | C21: =INDEX(評価項目対応!$F$6:$F$236,$U21) -> 3.07 | D21: =INDEX(評価項目対応!$D$6:$D$236,$U21) -> 脆弱性管理 | E21: =INDEX(評価項目対応!$E$6:$E$236,$U21) -> 特にインターネットに接続されたデバイス上の脆弱性を特定して対処する 。 | F21: =IF($D$4="","",$D$4) | G21: =IFERROR(IF(INDEX(評価項目対応!$I$6:$I$236,$U21)="対象","対象",IF(INDEX(評価項目対応!$I$6:$I$236,$U21)="対象外（承認済）","対象外",IF(INDEX(評価項目対応!$I$6:$I$236,$U21)="未確定","n/a",""))),"") -> n/a | H21: =IF(ISBLANK(J21),"",IF(J21=5,"Yes",IF(J21=4,"Yes","No"))) | M21: =IF(INDEX(評価項目対応!$J$6:$J$236,$U21)="","",INDEX(評価項目対応!$J$6:$J$236,$U21)) | N21: =IF(INDEX(評価項目対応!$N$6:$N$236,$U21)="","",INDEX(評価項目対応!$N$6:$N$236,$U21)) | O21: =IF(INDEX(評価項目対応!$O$6:$O$236,$U21)="","",INDEX(評価項目対応!$O$6:$O$236,$U21)) | P21: =COUNTIF(F21:G21,"")+COUNTIF(I21:O21,"")-IF(AND(G21="対象外",K21=""),1,0) -> 8 | Q21: =IF(F21="","会社名コード未設定（D4）",IF(OR(G21="",G21="n/a"),"適用性を確定（評価項目対応I列）",IF(AND(G21="対象外",OR(I21<>"対象外",J21<>"n/a")),"対象外ならR=対象外・S=n/a",IF(AND(G21="対象",OR(I21="対象外",J21="n/a")),"対象なのにR／Sが対象外・n/a",IF(AND(G21="対象",OR(I21="",J21="")),"R・Sを入力",IF(AND(ISNUMBER(J21),ISNUMBER(V21),ABS(N(J21)-N(V21))>=1),"RとSの乖離（案分ならUに明記）",IF(AND(G21="対象",L21=""),"Uに制約・代替策・未検証を記載",IF(AND(G21="対象外",L21=""),"対象外の理由・承認者をUに記載",IF(OR(M21="",N21="",O21=""),"V～Xを入力",IF(P21>0,"未記入あり（P列）","OK")))))))))) -> 会社名コード未設定（D4） | R21: =IF(INDEX(評価項目対応!$M$6:$M$236,$U21)="","",INDEX(評価項目対応!$M$6:$M$236,$U21)) | S21: =INDEX(評価項目対応!$H$6:$H$236,$U21) -> ChromeOSと接続先・ネットワーク製品を分けて脆弱性・更新運用を確認する。 | T21: =TRIM(IF(INDEX(評価項目対応!$K$6:$K$236,$U21)="","","試験ID: "&INDEX(評価項目対応!$K$6:$K$236,$U21)&" ")&IF(INDEX(評価項目対応!$L$6:$L$236,$U21)="","","判断理由: "&INDEX(評価項目対応!$L$6:$L$236,$U21))) | U21: =MATCH($A21,評価項目対応!$A$6:$A$236,0) -> 15 | V21: =IFERROR(VLOOKUP(I21,$X$6:$Y$11,2,FALSE()),"")
A22: 18 | B22: =INDEX(評価項目対応!$B$6:$B$236,$U22) -> 30 | C22: =INDEX(評価項目対応!$F$6:$F$236,$U22) -> 3.07 | D22: =INDEX(評価項目対応!$D$6:$D$236,$U22) -> 脆弱性管理 | E22: =INDEX(評価項目対応!$E$6:$E$236,$U22) -> インターネットデータ、Webブラウザ、ブラウザプラグイン、ドキュメン トリーダーなどを処理するソフトウェアを実行するインターネット向けサ ーバーへのパッチ適用を優先する。 | F22: =IF($D$4="","",$D$4) | G22: =IFERROR(IF(INDEX(評価項目対応!$I$6:$I$236,$U22)="対象","対象",IF(INDEX(評価項目対応!$I$6:$I$236,$U22)="対象外（承認済）","対象外",IF(INDEX(評価項目対応!$I$6:$I$236,$U22)="未確定","n/a",""))),"") -> n/a | H22: =IF(ISBLANK(J22),"",IF(J22=5,"Yes",IF(J22=4,"Yes","No"))) | M22: =IF(INDEX(評価項目対応!$J$6:$J$236,$U22)="","",INDEX(評価項目対応!$J$6:$J$236,$U22)) | N22: =IF(INDEX(評価項目対応!$N$6:$N$236,$U22)="","",INDEX(評価項目対応!$N$6:$N$236,$U22)) | O22: =IF(INDEX(評価項目対応!$O$6:$O$236,$U22)="","",INDEX(評価項目対応!$O$6:$O$236,$U22)) | P22: =COUNTIF(F22:G22,"")+COUNTIF(I22:O22,"")-IF(AND(G22="対象外",K22=""),1,0) -> 8 | Q22: =IF(F22="","会社名コード未設定（D4）",IF(OR(G22="",G22="n/a"),"適用性を確定（評価項目対応I列）",IF(AND(G22="対象外",OR(I22<>"対象外",J22<>"n/a")),"対象外ならR=対象外・S=n/a",IF(AND(G22="対象",OR(I22="対象外",J22="n/a")),"対象なのにR／Sが対象外・n/a",IF(AND(G22="対象",OR(I22="",J22="")),"R・Sを入力",IF(AND(ISNUMBER(J22),ISNUMBER(V22),ABS(N(J22)-N(V22))>=1),"RとSの乖離（案分ならUに明記）",IF(AND(G22="対象",L22=""),"Uに制約・代替策・未検証を記載",IF(AND(G22="対象外",L22=""),"対象外の理由・承認者をUに記載",IF(OR(M22="",N22="",O22=""),"V～Xを入力",IF(P22>0,"未記入あり（P列）","OK")))))))))) -> 会社名コード未設定（D4） | R22: =IF(INDEX(評価項目対応!$M$6:$M$236,$U22)="","",INDEX(評価項目対応!$M$6:$M$236,$U22)) | S22: =INDEX(評価項目対応!$H$6:$H$236,$U22) -> ChromeOSと接続先・ネットワーク製品を分けて脆弱性・更新運用を確認する。 | T22: =TRIM(IF(INDEX(評価項目対応!$K$6:$K$236,$U22)="","","試験ID: "&INDEX(評価項目対応!$K$6:$K$236,$U22)&" ")&IF(INDEX(評価項目対応!$L$6:$L$236,$U22)="","","判断理由: "&INDEX(評価項目対応!$L$6:$L$236,$U22))) | U22: =MATCH($A22,評価項目対応!$A$6:$A$236,0) -> 16 | V22: =IFERROR(VLOOKUP(I22,$X$6:$Y$11,2,FALSE()),"")
